Workbook

Sheet Options
A1: Idle Heroes Event Option Planner | Q1: Cost Settings
A2: Pick one reward per floor using the dropdowns. Normal rewards cost 10, discounted rewards cost 5, and Floor 13 - Free costs 0 after completing floors 1–12. | Q2: Normal | R2: 10
Q3: Discounted | R3: 5
A4: Option | B4: Floor 1 | C4: Floor 2 | D4: Floor 3 | E4: Floor 4 | F4: Floor 5 | G4: Floor 6 | H4: Floor 7 | I4: Floor 8 | J4: Floor 9 | K4: Floor 10 | L4: Floor 11 | M4: Floor 12 | N4: Floor 13 - Free | O4: Total Cost | P4: SG Cost | Q4: Floor 13 Free | R4: 0 | T4: Reward Counts | U4: Void | V4: Origin | W4: DT | X4: Star Soul | Y4: Artifacts | Z4: Origin Artifacts | AA4: Grim
A5: Best Free | B5: Void | C5: Origin | D5: Origin | O5: =SUMIFS(Rewards!$L$3:$L$45,Rewards!$J$3:$J$45,B$4,Rewards!$K$3:$K$45,B5)+SUMIFS(Rewards!$L$3:$L$45,Rewards!$J$3:$J$45,C$4,Rewards!$K$3:$K$45,C5)+SUMIFS(Rewards!$L$3:$L$45,Rewards!$J$3:$J$45,D$4,Rewards!$K$3:$K$45,D5)+SUMIFS(Rewards!$L$3:$L$45,Rewards!$J$3:$J$45,E$4,Rewards!$K$3:$K$45,E5)+SUMIFS(Rewards!$L$3:$L$45,Rewards!$J$3:$J$45,F$4,Rewards!$K$3:$K$45,F5)+SUMIFS(Rewards!$L$3:$L$45,Rewards!$J$3:$J$45,G$4,Rewards!$K$3:$K$45,G5)+SUMIFS(Rewards!$L$3:$L$45,Rewards!$J$3:$J$45,H$4,Rewards!$K$3:$K$45,H5)+SUMIFS(Rewards!$L$3:$L$45,Rewards!$J$3:$J$45,I$4,Rewards!$K$3:$K$45,I5)+SUMIFS(Rewards!$L$3:$L$45,Rewards!$J$3:$J$45,J$4,Rewards!$K$3:$K$45,J5)+SUMIFS(Rewards!$L$3:$L$45,Rewards!$J$3:$J$45,K$4,Rewards!$K$3:$K$45,K5)+SUMIFS(Rewards!$L$3:$L$45,Rewards!$J$3:$J$45,L$4,Rewards!$K$3:$K$45,L5)+SUMIFS(Rewards!$L$3:$L$45,Rewards!$J$3:$J$45,M$4,Rewards!$K$3:$K$45,M5)+SUMIFS(Rewards!$L$3:$L$45,Rewards!$J$3:$J$45,N$4,Rewards!$K$3:$K$45,N5) -> 20 | P5: =IF($O5<=20,0,IF($O5<=45,2750,IF($O5<=50,3750,IF($O5<=65,6500,IF($O5<=70,7500,""))))) -> 0 | T5: Option 1 | U5: =COUNTIF($B5:$N5,U$4) -> 1 | V5: =COUNTIF($B5:$N5,V$4) -> 2 | W5: =COUNTIF($B5:$N5,W$4) -> 0 | X5: =COUNTIF($B5:$N5,X$4) -> 0 | Y5: =COUNTIF($B5:$N5,Y$4) -> 0 | Z5: =COUNTIF($B5:$N5,Z$4) -> 0 | AA5: =COUNTIF($B5:$N5,AA$4) -> 0
A6: Option 2 | B6: Void | C6: Void | D6: Origin | E6: Void | O6: =SUMIFS(Rewards!$L$3:$L$45,Rewards!$J$3:$J$45,B$4,Rewards!$K$3:$K$45,B6)+SUMIFS(Rewards!$L$3:$L$45,Rewards!$J$3:$J$45,C$4,Rewards!$K$3:$K$45,C6)+SUMIFS(Rewards!$L$3:$L$45,Rewards!$J$3:$J$45,D$4,Rewards!$K$3:$K$45,D6)+SUMIFS(Rewards!$L$3:$L$45,Rewards!$J$3:$J$45,E$4,Rewards!$K$3:$K$45,E6)+SUMIFS(Rewards!$L$3:$L$45,Rewards!$J$3:$J$45,F$4,Rewards!$K$3:$K$45,F6)+SUMIFS(Rewards!$L$3:$L$45,Rewards!$J$3:$J$45,G$4,Rewards!$K$3:$K$45,G6)+SUMIFS(Rewards!$L$3:$L$45,Rewards!$J$3:$J$45,H$4,Rewards!$K$3:$K$45,H6)+SUMIFS(Rewards!$L$3:$L$45,Rewards!$J$3:$J$45,I$4,Rewards!$K$3:$K$45,I6)+SUMIFS(Rewards!$L$3:$L$45,Rewards!$J$3:$J$45,J$4,Rewards!$K$3:$K$45,J6)+SUMIFS(Rewards!$L$3:$L$45,Rewards!$J$3:$J$45,K$4,Rewards!$K$3:$K$45,K6)+SUMIFS(Rewards!$L$3:$L$45,Rewards!$J$3:$J$45,L$4,Rewards!$K$3:$K$45,L6)+SUMIFS(Rewards!$L$3:$L$45,Rewards!$J$3:$J$45,M$4,Rewards!$K$3:$K$45,M6)+SUMIFS(Rewards!$L$3:$L$45,Rewards!$J$3:$J$45,N$4,Rewards!$K$3:$K$45,N6) -> 20 | P6: =IF($O6<=20,0,IF($O6<=45,2750,IF($O6<=50,3750,IF($O6<=65,6500,IF($O6<=70,7500,""))))) -> 0 | Q6: SG Cost Table | T6: Option 2 | U6: =COUNTIF($B6:$N6,U$4) -> 3 | V6: =COUNTIF($B6:$N6,V$4) -> 1 | W6: =COUNTIF($B6:$N6,W$4) -> 0 | X6: =COUNTIF($B6:$N6,X$4) -> 0 | Y6: =COUNTIF($B6:$N6,Y$4) -> 0 | Z6: =COUNTIF($B6:$N6,Z$4) -> 0 | AA6: =COUNTIF($B6:$N6,AA$4) -> 0
A7: Option 3 | B7: Artifacts | C7: Artifacts | O7: =SUMIFS(Rewards!$L$3:$L$45,Rewards!$J$3:$J$45,B$4,Rewards!$K$3:$K$45,B7)+SUMIFS(Rewards!$L$3:$L$45,Rewards!$J$3:$J$45,C$4,Rewards!$K$3:$K$45,C7)+SUMIFS(Rewards!$L$3:$L$45,Rewards!$J$3:$J$45,D$4,Rewards!$K$3:$K$45,D7)+SUMIFS(Rewards!$L$3:$L$45,Rewards!$J$3:$J$45,E$4,Rewards!$K$3:$K$45,E7)+SUMIFS(Rewards!$L$3:$L$45,Rewards!$J$3:$J$45,F$4,Rewards!$K$3:$K$45,F7)+SUMIFS(Rewards!$L$3:$L$45,Rewards!$J$3:$J$45,G$4,Rewards!$K$3:$K$45,G7)+SUMIFS(Rewards!$L$3:$L$45,Rewards!$J$3:$J$45,H$4,Rewards!$K$3:$K$45,H7)+SUMIFS(Rewards!$L$3:$L$45,Rewards!$J$3:$J$45,I$4,Rewards!$K$3:$K$45,I7)+SUMIFS(Rewards!$L$3:$L$45,Rewards!$J$3:$J$45,J$4,Rewards!$K$3:$K$45,J7)+SUMIFS(Rewards!$L$3:$L$45,Rewards!$J$3:$J$45,K$4,Rewards!$K$3:$K$45,K7)+SUMIFS(Rewards!$L$3:$L$45,Rewards!$J$3:$J$45,L$4,Rewards!$K$3:$K$45,L7)+SUMIFS(Rewards!$L$3:$L$45,Rewards!$J$3:$J$45,M$4,Rewards!$K$3:$K$45,M7)+SUMIFS(Rewards!$L$3:$L$45,Rewards!$J$3:$J$45,N$4,Rewards!$K$3:$K$45,N7) -> 20 | P7: =IF($O7<=20,0,IF($O7<=45,2750,IF($O7<=50,3750,IF($O7<=65,6500,IF($O7<=70,7500,""))))) -> 0 | Q7: Total Cost <= | R7: SG Cost | T7: Option 3 | U7: =COUNTIF($B7:$N7,U$4) -> 0 | V7: =COUNTIF($B7:$N7,V$4) -> 0 | W7: =COUNTIF($B7:$N7,W$4) -> 0 | X7: =COUNTIF($B7:$N7,X$4) -> 0 | Y7: =COUNTIF($B7:$N7,Y$4) -> 2 | Z7: =COUNTIF($B7:$N7,Z$4) -> 0 | AA7: =COUNTIF($B7:$N7,AA$4) -> 0
A8: Option 4 | O8: =SUMIFS(Rewards!$L$3:$L$45,Rewards!$J$3:$J$45,B$4,Rewards!$K$3:$K$45,B8)+SUMIFS(Rewards!$L$3:$L$45,Rewards!$J$3:$J$45,C$4,Rewards!$K$3:$K$45,C8)+SUMIFS(Rewards!$L$3:$L$45,Rewards!$J$3:$J$45,D$4,Rewards!$K$3:$K$45,D8)+SUMIFS(Rewards!$L$3:$L$45,Rewards!$J$3:$J$45,E$4,Rewards!$K$3:$K$45,E8)+SUMIFS(Rewards!$L$3:$L$45,Rewards!$J$3:$J$45,F$4,Rewards!$K$3:$K$45,F8)+SUMIFS(Rewards!$L$3:$L$45,Rewards!$J$3:$J$45,G$4,Rewards!$K$3:$K$45,G8)+SUMIFS(Rewards!$L$3:$L$45,Rewards!$J$3:$J$45,H$4,Rewards!$K$3:$K$45,H8)+SUMIFS(Rewards!$L$3:$L$45,Rewards!$J$3:$J$45,I$4,Rewards!$K$3:$K$45,I8)+SUMIFS(Rewards!$L$3:$L$45,Rewards!$J$3:$J$45,J$4,Rewards!$K$3:$K$45,J8)+SUMIFS(Rewards!$L$3:$L$45,Rewards!$J$3:$J$45,K$4,Rewards!$K$3:$K$45,K8)+SUMIFS(Rewards!$L$3:$L$45,Rewards!$J$3:$J$45,L$4,Rewards!$K$3:$K$45,L8)+SUMIFS(Rewards!$L$3:$L$45,Rewards!$J$3:$J$45,M$4,Rewards!$K$3:$K$45,M8)+SUMIFS(Rewards!$L$3:$L$45,Rewards!$J$3:$J$45,N$4,Rewards!$K$3:$K$45,N8) -> 0 | P8: =IF($O8<=20,0,IF($O8<=45,2750,IF($O8<=50,3750,IF($O8<=65,6500,IF($O8<=70,7500,""))))) -> 0 | Q8: 20 | R8: 0 | T8: Option 4 | U8: =COUNTIF($B8:$N8,U$4) -> 0 | V8: =COUNTIF($B8:$N8,V$4) -> 0 | W8: =COUNTIF($B8:$N8,W$4) -> 0 | X8: =COUNTIF($B8:$N8,X$4) -> 0 | Y8: =COUNTIF($B8:$N8,Y$4) -> 0 | Z8: =COUNTIF($B8:$N8,Z$4) -> 0 | AA8: =COUNTIF($B8:$N8,AA$4) -> 0
A9: Option 5 | O9: =SUMIFS(Rewards!$L$3:$L$45,Rewards!$J$3:$J$45,B$4,Rewards!$K$3:$K$45,B9)+SUMIFS(Rewards!$L$3:$L$45,Rewards!$J$3:$J$45,C$4,Rewards!$K$3:$K$45,C9)+SUMIFS(Rewards!$L$3:$L$45,Rewards!$J$3:$J$45,D$4,Rewards!$K$3:$K$45,D9)+SUMIFS(Rewards!$L$3:$L$45,Rewards!$J$3:$J$45,E$4,Rewards!$K$3:$K$45,E9)+SUMIFS(Rewards!$L$3:$L$45,Rewards!$J$3:$J$45,F$4,Rewards!$K$3:$K$45,F9)+SUMIFS(Rewards!$L$3:$L$45,Rewards!$J$3:$J$45,G$4,Rewards!$K$3:$K$45,G9)+SUMIFS(Rewards!$L$3:$L$45,Rewards!$J$3:$J$45,H$4,Rewards!$K$3:$K$45,H9)+SUMIFS(Rewards!$L$3:$L$45,Rewards!$J$3:$J$45,I$4,Rewards!$K$3:$K$45,I9)+SUMIFS(Rewards!$L$3:$L$45,Rewards!$J$3:$J$45,J$4,Rewards!$K$3:$K$45,J9)+SUMIFS(Rewards!$L$3:$L$45,Rewards!$J$3:$J$45,K$4,Rewards!$K$3:$K$45,K9)+SUMIFS(Rewards!$L$3:$L$45,Rewards!$J$3:$J$45,L$4,Rewards!$K$3:$K$45,L9)+SUMIFS(Rewards!$L$3:$L$45,Rewards!$J$3:$J$45,M$4,Rewards!$K$3:$K$45,M9)+SUMIFS(Rewards!$L$3:$L$45,Rewards!$J$3:$J$45,N$4,Rewards!$K$3:$K$45,N9) -> 0 | P9: =IF($O9<=20,0,IF($O9<=45,2750,IF($O9<=50,3750,IF($O9<=65,6500,IF($O9<=70,7500,""))))) -> 0 | Q9: 45 | R9: 2750 | T9: Option 5 | U9: =COUNTIF($B9:$N9,U$4) -> 0 | V9: =COUNTIF($B9:$N9,V$4) -> 0 | W9: =COUNTIF($B9:$N9,W$4) -> 0 | X9: =COUNTIF($B9:$N9,X$4) -> 0 | Y9: =COUNTIF($B9:$N9,Y$4) -> 0 | Z9: =COUNTIF($B9:$N9,Z$4) -> 0 | AA9: =COUNTIF($B9:$N9,AA$4) -> 0
A10: Origin Art Hunt 1 | B10: Void | C10: Void | D10: Origin | E10: Origin Artifacts | F10: Origin Artifacts | G10: Origin | H10: Origin | O10: =SUMIFS(Rewards!$L$3:$L$45,Rewards!$J$3:$J$45,B$4,Rewards!$K$3:$K$45,B10)+SUMIFS(Rewards!$L$3:$L$45,Rewards!$J$3:$J$45,C$4,Rewards!$K$3:$K$45,C10)+SUMIFS(Rewards!$L$3:$L$45,Rewards!$J$3:$J$45,D$4,Rewards!$K$3:$K$45,D10)+SUMIFS(Rewards!$L$3:$L$45,Rewards!$J$3:$J$45,E$4,Rewards!$K$3:$K$45,E10)+SUMIFS(Rewards!$L$3:$L$45,Rewards!$J$3:$J$45,F$4,Rewards!$K$3:$K$45,F10)+SUMIFS(Rewards!$L$3:$L$45,Rewards!$J$3:$J$45,G$4,Rewards!$K$3:$K$45,G10)+SUMIFS(Rewards!$L$3:$L$45,Rewards!$J$3:$J$45,H$4,Rewards!$K$3:$K$45,H10)+SUMIFS(Rewards!$L$3:$L$45,Rewards!$J$3:$J$45,I$4,Rewards!$K$3:$K$45,I10)+SUMIFS(Rewards!$L$3:$L$45,Rewards!$J$3:$J$45,J$4,Rewards!$K$3:$K$45,J10)+SUMIFS(Rewards!$L$3:$L$45,Rewards!$J$3:$J$45,K$4,Rewards!$K$3:$K$45,K10)+SUMIFS(Rewards!$L$3:$L$45,Rewards!$J$3:$J$45,L$4,Rewards!$K$3:$K$45,L10)+SUMIFS(Rewards!$L$3:$L$45,Rewards!$J$3:$J$45,M$4,Rewards!$K$3:$K$45,M10)+SUMIFS(Rewards!$L$3:$L$45,Rewards!$J$3:$J$45,N$4,Rewards!$K$3:$K$45,N10) -> 45 | P10: =IF($O10<=20,0,IF($O10<=45,2750,IF($O10<=50,3750,IF($O10<=65,6500,IF($O10<=70,7500,""))))) -> 2750 | Q10: 50 | R10: 3750 | T10: Option 6 | U10: =COUNTIF($B10:$N10,U$4) -> 2 | V10: =COUNTIF($B10:$N10,V$4) -> 3 | W10: =COUNTIF($B10:$N10,W$4) -> 0 | X10: =COUNTIF($B10:$N10,X$4) -> 0 | Y10: =COUNTIF($B10:$N10,Y$4) -> 0 | Z10: =COUNTIF($B10:$N10,Z$4) -> 2 | AA10: =COUNTIF($B10:$N10,AA$4) -> 0
A11: Origin Art Hunt 2 | B11: Void | C11: Void | D11: Origin | E11: Origin Artifacts | F11: Origin Artifacts | G11: DT | O11: =SUMIFS(Rewards!$L$3:$L$45,Rewards!$J$3:$J$45,B$4,Rewards!$K$3:$K$45,B11)+SUMIFS(Rewards!$L$3:$L$45,Rewards!$J$3:$J$45,C$4,Rewards!$K$3:$K$45,C11)+SUMIFS(Rewards!$L$3:$L$45,Rewards!$J$3:$J$45,D$4,Rewards!$K$3:$K$45,D11)+SUMIFS(Rewards!$L$3:$L$45,Rewards!$J$3:$J$45,E$4,Rewards!$K$3:$K$45,E11)+SUMIFS(Rewards!$L$3:$L$45,Rewards!$J$3:$J$45,F$4,Rewards!$K$3:$K$45,F11)+SUMIFS(Rewards!$L$3:$L$45,Rewards!$J$3:$J$45,G$4,Rewards!$K$3:$K$45,G11)+SUMIFS(Rewards!$L$3:$L$45,Rewards!$J$3:$J$45,H$4,Rewards!$K$3:$K$45,H11)+SUMIFS(Rewards!$L$3:$L$45,Rewards!$J$3:$J$45,I$4,Rewards!$K$3:$K$45,I11)+SUMIFS(Rewards!$L$3:$L$45,Rewards!$J$3:$J$45,J$4,Rewards!$K$3:$K$45,J11)+SUMIFS(Rewards!$L$3:$L$45,Rewards!$J$3:$J$45,K$4,Rewards!$K$3:$K$45,K11)+SUMIFS(Rewards!$L$3:$L$45,Rewards!$J$3:$J$45,L$4,Rewards!$K$3:$K$45,L11)+SUMIFS(Rewards!$L$3:$L$45,Rewards!$J$3:$J$45,M$4,Rewards!$K$3:$K$45,M11)+SUMIFS(Rewards!$L$3:$L$45,Rewards!$J$3:$J$45,N$4,Rewards!$K$3:$K$45,N11) -> 45 | P11: =IF($O11<=20,0,IF($O11<=45,2750,IF($O11<=50,3750,IF($O11<=65,6500,IF($O11<=70,7500,""))))) -> 2750 | Q11: 65 | R11: 6500 | T11: Option 7 | U11: =COUNTIF($B11:$N11,U$4) -> 2 | V11: =COUNTIF($B11:$N11,V$4) -> 1 | W11: =COUNTIF($B11:$N11,W$4) -> 1 | X11: =COUNTIF($B11:$N11,X$4) -> 0 | Y11: =COUNTIF($B11:$N11,Y$4) -> 0 | Z11: =COUNTIF($B11:$N11,Z$4) -> 2 | AA11: =COUNTIF($B11:$N11,AA$4) -> 0
A12: Origin Hunt | B12: Void | C12: Void | D12: Origin | E12: Void | F12: Void | G12: Origin | H12: Origin | I12: Origin | J12: Origin | O12: =SUMIFS(Rewards!$L$3:$L$45,Rewards!$J$3:$J$45,B$4,Rewards!$K$3:$K$45,B12)+SUMIFS(Rewards!$L$3:$L$45,Rewards!$J$3:$J$45,C$4,Rewards!$K$3:$K$45,C12)+SUMIFS(Rewards!$L$3:$L$45,Rewards!$J$3:$J$45,D$4,Rewards!$K$3:$K$45,D12)+SUMIFS(Rewards!$L$3:$L$45,Rewards!$J$3:$J$45,E$4,Rewards!$K$3:$K$45,E12)+SUMIFS(Rewards!$L$3:$L$45,Rewards!$J$3:$J$45,F$4,Rewards!$K$3:$K$45,F12)+SUMIFS(Rewards!$L$3:$L$45,Rewards!$J$3:$J$45,G$4,Rewards!$K$3:$K$45,G12)+SUMIFS(Rewards!$L$3:$L$45,Rewards!$J$3:$J$45,H$4,Rewards!$K$3:$K$45,H12)+SUMIFS(Rewards!$L$3:$L$45,Rewards!$J$3:$J$45,I$4,Rewards!$K$3:$K$45,I12)+SUMIFS(Rewards!$L$3:$L$45,Rewards!$J$3:$J$45,J$4,Rewards!$K$3:$K$45,J12)+SUMIFS(Rewards!$L$3:$L$45,Rewards!$J$3:$J$45,K$4,Rewards!$K$3:$K$45,K12)+SUMIFS(Rewards!$L$3:$L$45,Rewards!$J$3:$J$45,L$4,Rewards!$K$3:$K$45,L12)+SUMIFS(Rewards!$L$3:$L$45,Rewards!$J$3:$J$45,M$4,Rewards!$K$3:$K$45,M12)+SUMIFS(Rewards!$L$3:$L$45,Rewards!$J$3:$J$45,N$4,Rewards!$K$3:$K$45,N12) -> 45 | P12: =IF($O12<=20,0,IF($O12<=45,2750,IF($O12<=50,3750,IF($O12<=65,6500,IF($O12<=70,7500,""))))) -> 2750 | Q12: 70 | R12: 7500 | T12: Option 8 | U12: =COUNTIF($B12:$N12,U$4) -> 4 | V12: =COUNTIF($B12:$N12,V$4) -> 5 | W12: =COUNTIF($B12:$N12,W$4) -> 0 | X12: =COUNTIF($B12:$N12,X$4) -> 0 | Y12: =COUNTIF($B12:$N12,Y$4) -> 0 | Z12: =COUNTIF($B12:$N12,Z$4) -> 0 | AA12: =COUNTIF($B12:$N12,AA$4) -> 0
A13: Balanced 45 | B13: Void | C13: Void | D13: Origin | E13: Void | F13: DT | G13: Origin | H13: Grim | O13: =SUMIFS(Rewards!$L$3:$L$45,Rewards!$J$3:$J$45,B$4,Rewards!$K$3:$K$45,B13)+SUMIFS(Rewards!$L$3:$L$45,Rewards!$J$3:$J$45,C$4,Rewards!$K$3:$K$45,C13)+SUMIFS(Rewards!$L$3:$L$45,Rewards!$J$3:$J$45,D$4,Rewards!$K$3:$K$45,D13)+SUMIFS(Rewards!$L$3:$L$45,Rewards!$J$3:$J$45,E$4,Rewards!$K$3:$K$45,E13)+SUMIFS(Rewards!$L$3:$L$45,Rewards!$J$3:$J$45,F$4,Rewards!$K$3:$K$45,F13)+SUMIFS(Rewards!$L$3:$L$45,Rewards!$J$3:$J$45,G$4,Rewards!$K$3:$K$45,G13)+SUMIFS(Rewards!$L$3:$L$45,Rewards!$J$3:$J$45,H$4,Rewards!$K$3:$K$45,H13)+SUMIFS(Rewards!$L$3:$L$45,Rewards!$J$3:$J$45,I$4,Rewards!$K$3:$K$45,I13)+SUMIFS(Rewards!$L$3:$L$45,Rewards!$J$3:$J$45,J$4,Rewards!$K$3:$K$45,J13)+SUMIFS(Rewards!$L$3:$L$45,Rewards!$J$3:$J$45,K$4,Rewards!$K$3:$K$45,K13)+SUMIFS(Rewards!$L$3:$L$45,Rewards!$J$3:$J$45,L$4,Rewards!$K$3:$K$45,L13)+SUMIFS(Rewards!$L$3:$L$45,Rewards!$J$3:$J$45,M$4,Rewards!$K$3:$K$45,M13)+SUMIFS(Rewards!$L$3:$L$45,Rewards!$J$3:$J$45,N$4,Rewards!$K$3:$K$45,N13) -> 45 | P13: =IF($O13<=20,0,IF($O13<=45,2750,IF($O13<=50,3750,IF($O13<=65,6500,IF($O13<=70,7500,""))))) -> 2750 | T13: Option 9 | U13: =COUNTIF($B13:$N13,U$4) -> 3 | V13: =COUNTIF($B13:$N13,V$4) -> 2 | W13: =COUNTIF($B13:$N13,W$4) -> 1 | X13: =COUNTIF($B13:$N13,X$4) -> 0 | Y13: =COUNTIF($B13:$N13,Y$4) -> 0 | Z13: =COUNTIF($B13:$N13,Z$4) -> 0 | AA13: =COUNTIF($B13:$N13,AA$4) -> 1
A14: Option 10 | B14: Void | C14: Void | D14: Origin | E14: Void | F14: Void | G14: Origin | H14: Grim | I14: Origin | O14: =SUMIFS(Rewards!$L$3:$L$45,Rewards!$J$3:$J$45,B$4,Rewards!$K$3:$K$45,B14)+SUMIFS(Rewards!$L$3:$L$45,Rewards!$J$3:$J$45,C$4,Rewards!$K$3:$K$45,C14)+SUMIFS(Rewards!$L$3:$L$45,Rewards!$J$3:$J$45,D$4,Rewards!$K$3:$K$45,D14)+SUMIFS(Rewards!$L$3:$L$45,Rewards!$J$3:$J$45,E$4,Rewards!$K$3:$K$45,E14)+SUMIFS(Rewards!$L$3:$L$45,Rewards!$J$3:$J$45,F$4,Rewards!$K$3:$K$45,F14)+SUMIFS(Rewards!$L$3:$L$45,Rewards!$J$3:$J$45,G$4,Rewards!$K$3:$K$45,G14)+SUMIFS(Rewards!$L$3:$L$45,Rewards!$J$3:$J$45,H$4,Rewards!$K$3:$K$45,H14)+SUMIFS(Rewards!$L$3:$L$45,Rewards!$J$3:$J$45,I$4,Rewards!$K$3:$K$45,I14)+SUMIFS(Rewards!$L$3:$L$45,Rewards!$J$3:$J$45,J$4,Rewards!$K$3:$K$45,J14)+SUMIFS(Rewards!$L$3:$L$45,Rewards!$J$3:$J$45,K$4,Rewards!$K$3:$K$45,K14)+SUMIFS(Rewards!$L$3:$L$45,Rewards!$J$3:$J$45,L$4,Rewards!$K$3:$K$45,L14)+SUMIFS(Rewards!$L$3:$L$45,Rewards!$J$3:$J$45,M$4,Rewards!$K$3:$K$45,M14)+SUMIFS(Rewards!$L$3:$L$45,Rewards!$J$3:$J$45,N$4,Rewards!$K$3:$K$45,N14) -> 45 | P14: =IF($O14<=20,0,IF($O14<=45,2750,IF($O14<=50,3750,IF($O14<=65,6500,IF($O14<=70,7500,""))))) -> 2750 | T14: Option 10 | U14: =COUNTIF($B14:$N14,U$4) -> 4 | V14: =COUNTIF($B14:$N14,V$4) -> 3 | W14: =COUNTIF($B14:$N14,W$4) -> 0 | X14: =COUNTIF($B14:$N14,X$4) -> 0 | Y14: =COUNTIF($B14:$N14,Y$4) -> 0 | Z14: =COUNTIF($B14:$N14,Z$4) -> 0 | AA14: =COUNTIF($B14:$N14,AA$4) -> 1
A15: Option 11 | B15: Void | C15: Void | D15: Origin | E15: Void | F15: DT | G15: DT | H15: Origin | O15: =SUMIFS(Rewards!$L$3:$L$45,Rewards!$J$3:$J$45,B$4,Rewards!$K$3:$K$45,B15)+SUMIFS(Rewards!$L$3:$L$45,Rewards!$J$3:$J$45,C$4,Rewards!$K$3:$K$45,C15)+SUMIFS(Rewards!$L$3:$L$45,Rewards!$J$3:$J$45,D$4,Rewards!$K$3:$K$45,D15)+SUMIFS(Rewards!$L$3:$L$45,Rewards!$J$3:$J$45,E$4,Rewards!$K$3:$K$45,E15)+SUMIFS(Rewards!$L$3:$L$45,Rewards!$J$3:$J$45,F$4,Rewards!$K$3:$K$45,F15)+SUMIFS(Rewards!$L$3:$L$45,Rewards!$J$3:$J$45,G$4,Rewards!$K$3:$K$45,G15)+SUMIFS(Rewards!$L$3:$L$45,Rewards!$J$3:$J$45,H$4,Rewards!$K$3:$K$45,H15)+SUMIFS(Rewards!$L$3:$L$45,Rewards!$J$3:$J$45,I$4,Rewards!$K$3:$K$45,I15)+SUMIFS(Rewards!$L$3:$L$45,Rewards!$J$3:$J$45,J$4,Rewards!$K$3:$K$45,J15)+SUMIFS(Rewards!$L$3:$L$45,Rewards!$J$3:$J$45,K$4,Rewards!$K$3:$K$45,K15)+SUMIFS(Rewards!$L$3:$L$45,Rewards!$J$3:$J$45,L$4,Rewards!$K$3:$K$45,L15)+SUMIFS(Rewards!$L$3:$L$45,Rewards!$J$3:$J$45,M$4,Rewards!$K$3:$K$45,M15)+SUMIFS(Rewards!$L$3:$L$45,Rewards!$J$3:$J$45,N$4,Rewards!$K$3:$K$45,N15) -> 45 | P15: =IF($O15<=20,0,IF($O15<=45,2750,IF($O15<=50,3750,IF($O15<=65,6500,IF($O15<=70,7500,""))))) -> 2750 | T15: Option 11 | U15: =COUNTIF($B15:$N15,U$4) -> 3 | V15: =COUNTIF($B15:$N15,V$4) -> 2 | W15: =COUNTIF($B15:$N15,W$4) -> 2 | X15: =COUNTIF($B15:$N15,X$4) -> 0 | Y15: =COUNTIF($B15:$N15,Y$4) -> 0 | Z15: =COUNTIF($B15:$N15,Z$4) -> 0 | AA15: =COUNTIF($B15:$N15,AA$4) -> 0
A16: DT hunt 55 | B16: Void | C16: Void | D16: Origin | E16: DT | F16: DT | G16: DT | O16: =SUMIFS(Rewards!$L$3:$L$45,Rewards!$J$3:$J$45,B$4,Rewards!$K$3:$K$45,B16)+SUMIFS(Rewards!$L$3:$L$45,Rewards!$J$3:$J$45,C$4,Rewards!$K$3:$K$45,C16)+SUMIFS(Rewards!$L$3:$L$45,Rewards!$J$3:$J$45,D$4,Rewards!$K$3:$K$45,D16)+SUMIFS(Rewards!$L$3:$L$45,Rewards!$J$3:$J$45,E$4,Rewards!$K$3:$K$45,E16)+SUMIFS(Rewards!$L$3:$L$45,Rewards!$J$3:$J$45,F$4,Rewards!$K$3:$K$45,F16)+SUMIFS(Rewards!$L$3:$L$45,Rewards!$J$3:$J$45,G$4,Rewards!$K$3:$K$45,G16)+SUMIFS(Rewards!$L$3:$L$45,Rewards!$J$3:$J$45,H$4,Rewards!$K$3:$K$45,H16)+SUMIFS(Rewards!$L$3:$L$45,Rewards!$J$3:$J$45,I$4,Rewards!$K$3:$K$45,I16)+SUMIFS(Rewards!$L$3:$L$45,Rewards!$J$3:$J$45,J$4,Rewards!$K$3:$K$45,J16)+SUMIFS(Rewards!$L$3:$L$45,Rewards!$J$3:$J$45,K$4,Rewards!$K$3:$K$45,K16)+SUMIFS(Rewards!$L$3:$L$45,Rewards!$J$3:$J$45,L$4,Rewards!$K$3:$K$45,L16)+SUMIFS(Rewards!$L$3:$L$45,Rewards!$J$3:$J$45,M$4,Rewards!$K$3:$K$45,M16)+SUMIFS(Rewards!$L$3:$L$45,Rewards!$J$3:$J$45,N$4,Rewards!$K$3:$K$45,N16) -> 45 | P16: =IF($O16<=20,0,IF($O16<=45,2750,IF($O16<=50,3750,IF($O16<=65,6500,IF($O16<=70,7500,""))))) -> 2750 | T16: Option 12 | U16: =COUNTIF($B16:$N16,U$4) -> 2 | V16: =COUNTIF($B16:$N16,V$4) -> 1 | W16: =COUNTIF($B16:$N16,W$4) -> 3 | X16: =COUNTIF($B16:$N16,X$4) -> 0 | Y16: =COUNTIF($B16:$N16,Y$4) -> 0 | Z16: =COUNTIF($B16:$N16,Z$4) -> 0 | AA16: =COUNTIF($B16:$N16,AA$4) -> 0
A17: Option 13 | B17: Void | C17: Void | D17: Origin | E17: DT | F17: DT | G17: Origin | H17: Origin | O17: =SUMIFS(Rewards!$L$3:$L$45,Rewards!$J$3:$J$45,B$4,Rewards!$K$3:$K$45,B17)+SUMIFS(Rewards!$L$3:$L$45,Rewards!$J$3:$J$45,C$4,Rewards!$K$3:$K$45,C17)+SUMIFS(Rewards!$L$3:$L$45,Rewards!$J$3:$J$45,D$4,Rewards!$K$3:$K$45,D17)+SUMIFS(Rewards!$L$3:$L$45,Rewards!$J$3:$J$45,E$4,Rewards!$K$3:$K$45,E17)+SUMIFS(Rewards!$L$3:$L$45,Rewards!$J$3:$J$45,F$4,Rewards!$K$3:$K$45,F17)+SUMIFS(Rewards!$L$3:$L$45,Rewards!$J$3:$J$45,G$4,Rewards!$K$3:$K$45,G17)+SUMIFS(Rewards!$L$3:$L$45,Rewards!$J$3:$J$45,H$4,Rewards!$K$3:$K$45,H17)+SUMIFS(Rewards!$L$3:$L$45,Rewards!$J$3:$J$45,I$4,Rewards!$K$3:$K$45,I17)+SUMIFS(Rewards!$L$3:$L$45,Rewards!$J$3:$J$45,J$4,Rewards!$K$3:$K$45,J17)+SUMIFS(Rewards!$L$3:$L$45,Rewards!$J$3:$J$45,K$4,Rewards!$K$3:$K$45,K17)+SUMIFS(Rewards!$L$3:$L$45,Rewards!$J$3:$J$45,L$4,Rewards!$K$3:$K$45,L17)+SUMIFS(Rewards!$L$3:$L$45,Rewards!$J$3:$J$45,M$4,Rewards!$K$3:$K$45,M17)+SUMIFS(Rewards!$L$3:$L$45,Rewards!$J$3:$J$45,N$4,Rewards!$K$3:$K$45,N17) -> 45 | P17: =IF($O17<=20,0,IF($O17<=45,2750,IF($O17<=50,3750,IF($O17<=65,6500,IF($O17<=70,7500,""))))) -> 2750 | T17: Option 13 | U17: =COUNTIF($B17:$N17,U$4) -> 2 | V17: =COUNTIF($B17:$N17,V$4) -> 3 | W17: =COUNTIF($B17:$N17,W$4) -> 2 | X17: =COUNTIF($B17:$N17,X$4) -> 0 | Y17: =COUNTIF($B17:$N17,Y$4) -> 0 | Z17: =COUNTIF($B17:$N17,Z$4) -> 0 | AA17: =COUNTIF($B17:$N17,AA$4) -> 0
A18: Option 14 | B18: Void | C18: Void | D18: Origin | E18: Void | F18: DT | G18: DT | H18: Grim | O18: =SUMIFS(Rewards!$L$3:$L$45,Rewards!$J$3:$J$45,B$4,Rewards!$K$3:$K$45,B18)+SUMIFS(Rewards!$L$3:$L$45,Rewards!$J$3:$J$45,C$4,Rewards!$K$3:$K$45,C18)+SUMIFS(Rewards!$L$3:$L$45,Rewards!$J$3:$J$45,D$4,Rewards!$K$3:$K$45,D18)+SUMIFS(Rewards!$L$3:$L$45,Rewards!$J$3:$J$45,E$4,Rewards!$K$3:$K$45,E18)+SUMIFS(Rewards!$L$3:$L$45,Rewards!$J$3:$J$45,F$4,Rewards!$K$3:$K$45,F18)+SUMIFS(Rewards!$L$3:$L$45,Rewards!$J$3:$J$45,G$4,Rewards!$K$3:$K$45,G18)+SUMIFS(Rewards!$L$3:$L$45,Rewards!$J$3:$J$45,H$4,Rewards!$K$3:$K$45,H18)+SUMIFS(Rewards!$L$3:$L$45,Rewards!$J$3:$J$45,I$4,Rewards!$K$3:$K$45,I18)+SUMIFS(Rewards!$L$3:$L$45,Rewards!$J$3:$J$45,J$4,Rewards!$K$3:$K$45,J18)+SUMIFS(Rewards!$L$3:$L$45,Rewards!$J$3:$J$45,K$4,Rewards!$K$3:$K$45,K18)+SUMIFS(Rewards!$L$3:$L$45,Rewards!$J$3:$J$45,L$4,Rewards!$K$3:$K$45,L18)+SUMIFS(Rewards!$L$3:$L$45,Rewards!$J$3:$J$45,M$4,Rewards!$K$3:$K$45,M18)+SUMIFS(Rewards!$L$3:$L$45,Rewards!$J$3:$J$45,N$4,Rewards!$K$3:$K$45,N18) -> 50 | P18: =IF($O18<=20,0,IF($O18<=45,2750,IF($O18<=50,3750,IF($O18<=65,6500,IF($O18<=70,7500,""))))) -> 3750 | T18: Option 14 | U18: =COUNTIF($B18:$N18,U$4) -> 3 | V18: =COUNTIF($B18:$N18,V$4) -> 1 | W18: =COUNTIF($B18:$N18,W$4) -> 2 | X18: =COUNTIF($B18:$N18,X$4) -> 0 | Y18: =COUNTIF($B18:$N18,Y$4) -> 0 | Z18: =COUNTIF($B18:$N18,Z$4) -> 0 | AA18: =COUNTIF($B18:$N18,AA$4) -> 1
A19: Option 15 | O19: =SUMIFS(Rewards!$L$3:$L$45,Rewards!$J$3:$J$45,B$4,Rewards!$K$3:$K$45,B19)+SUMIFS(Rewards!$L$3:$L$45,Rewards!$J$3:$J$45,C$4,Rewards!$K$3:$K$45,C19)+SUMIFS(Rewards!$L$3:$L$45,Rewards!$J$3:$J$45,D$4,Rewards!$K$3:$K$45,D19)+SUMIFS(Rewards!$L$3:$L$45,Rewards!$J$3:$J$45,E$4,Rewards!$K$3:$K$45,E19)+SUMIFS(Rewards!$L$3:$L$45,Rewards!$J$3:$J$45,F$4,Rewards!$K$3:$K$45,F19)+SUMIFS(Rewards!$L$3:$L$45,Rewards!$J$3:$J$45,G$4,Rewards!$K$3:$K$45,G19)+SUMIFS(Rewards!$L$3:$L$45,Rewards!$J$3:$J$45,H$4,Rewards!$K$3:$K$45,H19)+SUMIFS(Rewards!$L$3:$L$45,Rewards!$J$3:$J$45,I$4,Rewards!$K$3:$K$45,I19)+SUMIFS(Rewards!$L$3:$L$45,Rewards!$J$3:$J$45,J$4,Rewards!$K$3:$K$45,J19)+SUMIFS(Rewards!$L$3:$L$45,Rewards!$J$3:$J$45,K$4,Rewards!$K$3:$K$45,K19)+SUMIFS(Rewards!$L$3:$L$45,Rewards!$J$3:$J$45,L$4,Rewards!$K$3:$K$45,L19)+SUMIFS(Rewards!$L$3:$L$45,Rewards!$J$3:$J$45,M$4,Rewards!$K$3:$K$45,M19)+SUMIFS(Rewards!$L$3:$L$45,Rewards!$J$3:$J$45,N$4,Rewards!$K$3:$K$45,N19) -> 0 | P19: =IF($O19<=20,0,IF($O19<=45,2750,IF($O19<=50,3750,IF($O19<=65,6500,IF($O19<=70,7500,""))))) -> 0 | T19: Option 15 | U19: =COUNTIF($B19:$N19,U$4) -> 0 | V19: =COUNTIF($B19:$N19,V$4) -> 0 | W19: =COUNTIF($B19:$N19,W$4) -> 0 | X19: =COUNTIF($B19:$N19,X$4) -> 0 | Y19: =COUNTIF($B19:$N19,Y$4) -> 0 | Z19: =COUNTIF($B19:$N19,Z$4) -> 0 | AA19: =COUNTIF($B19:$N19,AA$4) -> 0
A20: Balanced 65 | B20: Void | C20: Void | D20: Origin | E20: Void | F20: Void | G20: Origin | H20: Grim | I20: Origin | J20: Origin | K20: DT | L20: DT | M20: Origin | N20: Grim | O20: =SUMIFS(Rewards!$L$3:$L$45,Rewards!$J$3:$J$45,B$4,Rewards!$K$3:$K$45,B20)+SUMIFS(Rewards!$L$3:$L$45,Rewards!$J$3:$J$45,C$4,Rewards!$K$3:$K$45,C20)+SUMIFS(Rewards!$L$3:$L$45,Rewards!$J$3:$J$45,D$4,Rewards!$K$3:$K$45,D20)+SUMIFS(Rewards!$L$3:$L$45,Rewards!$J$3:$J$45,E$4,Rewards!$K$3:$K$45,E20)+SUMIFS(Rewards!$L$3:$L$45,Rewards!$J$3:$J$45,F$4,Rewards!$K$3:$K$45,F20)+SUMIFS(Rewards!$L$3:$L$45,Rewards!$J$3:$J$45,G$4,Rewards!$K$3:$K$45,G20)+SUMIFS(Rewards!$L$3:$L$45,Rewards!$J$3:$J$45,H$4,Rewards!$K$3:$K$45,H20)+SUMIFS(Rewards!$L$3:$L$45,Rewards!$J$3:$J$45,I$4,Rewards!$K$3:$K$45,I20)+SUMIFS(Rewards!$L$3:$L$45,Rewards!$J$3:$J$45,J$4,Rewards!$K$3:$K$45,J20)+SUMIFS(Rewards!$L$3:$L$45,Rewards!$J$3:$J$45,K$4,Rewards!$K$3:$K$45,K20)+SUMIFS(Rewards!$L$3:$L$45,Rewards!$J$3:$J$45,L$4,Rewards!$K$3:$K$45,L20)+SUMIFS(Rewards!$L$3:$L$45,Rewards!$J$3:$J$45,M$4,Rewards!$K$3:$K$45,M20)+SUMIFS(Rewards!$L$3:$L$45,Rewards!$J$3:$J$45,N$4,Rewards!$K$3:$K$45,N20) -> 65 | P20: =IF($O20<=20,0,IF($O20<=45,2750,IF($O20<=50,3750,IF($O20<=65,6500,IF($O20<=70,7500,""))))) -> 6500 | T20: Option 16 | U20: =COUNTIF($B20:$N20,U$4) -> 4 | V20: =COUNTIF($B20:$N20,V$4) -> 5 | W20: =COUNTIF($B20:$N20,W$4) -> 2 | X20: =COUNTIF($B20:$N20,X$4) -> 0 | Y20: =COUNTIF($B20:$N20,Y$4) -> 0 | Z20: =COUNTIF($B20:$N20,Z$4) -> 0 | AA20: =COUNTIF($B20:$N20,AA$4) -> 2
A21: Option 17 | B21: Void | C21: Void | D21: Origin | E21: Void | F21: Void | G21: Origin | H21: Grim | I21: Origin | J21: Origin | K21: DT | L21: DT | M21: DT | N21: Grim | O21: =SUMIFS(Rewards!$L$3:$L$45,Rewards!$J$3:$J$45,B$4,Rewards!$K$3:$K$45,B21)+SUMIFS(Rewards!$L$3:$L$45,Rewards!$J$3:$J$45,C$4,Rewards!$K$3:$K$45,C21)+SUMIFS(Rewards!$L$3:$L$45,Rewards!$J$3:$J$45,D$4,Rewards!$K$3:$K$45,D21)+SUMIFS(Rewards!$L$3:$L$45,Rewards!$J$3:$J$45,E$4,Rewards!$K$3:$K$45,E21)+SUMIFS(Rewards!$L$3:$L$45,Rewards!$J$3:$J$45,F$4,Rewards!$K$3:$K$45,F21)+SUMIFS(Rewards!$L$3:$L$45,Rewards!$J$3:$J$45,G$4,Rewards!$K$3:$K$45,G21)+SUMIFS(Rewards!$L$3:$L$45,Rewards!$J$3:$J$45,H$4,Rewards!$K$3:$K$45,H21)+SUMIFS(Rewards!$L$3:$L$45,Rewards!$J$3:$J$45,I$4,Rewards!$K$3:$K$45,I21)+SUMIFS(Rewards!$L$3:$L$45,Rewards!$J$3:$J$45,J$4,Rewards!$K$3:$K$45,J21)+SUMIFS(Rewards!$L$3:$L$45,Rewards!$J$3:$J$45,K$4,Rewards!$K$3:$K$45,K21)+SUMIFS(Rewards!$L$3:$L$45,Rewards!$J$3:$J$45,L$4,Rewards!$K$3:$K$45,L21)+SUMIFS(Rewards!$L$3:$L$45,Rewards!$J$3:$J$45,M$4,Rewards!$K$3:$K$45,M21)+SUMIFS(Rewards!$L$3:$L$45,Rewards!$J$3:$J$45,N$4,Rewards!$K$3:$K$45,N21) -> 70 | P21: =IF($O21<=20,0,IF($O21<=45,2750,IF($O21<=50,3750,IF($O21<=65,6500,IF($O21<=70,7500,""))))) -> 7500 | T21: Option 17 | U21: =COUNTIF($B21:$N21,U$4) -> 4 | V21: =COUNTIF($B21:$N21,V$4) -> 4 | W21: =COUNTIF($B21:$N21,W$4) -> 3 | X21: =COUNTIF($B21:$N21,X$4) -> 0 | Y21: =COUNTIF($B21:$N21,Y$4) -> 0 | Z21: =COUNTIF($B21:$N21,Z$4) -> 0 | AA21: =COUNTIF($B21:$N21,AA$4) -> 2
A22: Grim Hunt | B22: Void | C22: Void | D22: Origin | E22: Void | F22: Void | G22: Origin | H22: Grim | I22: Origin | J22: Origin | K22: Grim | L22: DT | M22: Origin | N22: Grim | O22: =SUMIFS(Rewards!$L$3:$L$45,Rewards!$J$3:$J$45,B$4,Rewards!$K$3:$K$45,B22)+SUMIFS(Rewards!$L$3:$L$45,Rewards!$J$3:$J$45,C$4,Rewards!$K$3:$K$45,C22)+SUMIFS(Rewards!$L$3:$L$45,Rewards!$J$3:$J$45,D$4,Rewards!$K$3:$K$45,D22)+SUMIFS(Rewards!$L$3:$L$45,Rewards!$J$3:$J$45,E$4,Rewards!$K$3:$K$45,E22)+SUMIFS(Rewards!$L$3:$L$45,Rewards!$J$3:$J$45,F$4,Rewards!$K$3:$K$45,F22)+SUMIFS(Rewards!$L$3:$L$45,Rewards!$J$3:$J$45,G$4,Rewards!$K$3:$K$45,G22)+SUMIFS(Rewards!$L$3:$L$45,Rewards!$J$3:$J$45,H$4,Rewards!$K$3:$K$45,H22)+SUMIFS(Rewards!$L$3:$L$45,Rewards!$J$3:$J$45,I$4,Rewards!$K$3:$K$45,I22)+SUMIFS(Rewards!$L$3:$L$45,Rewards!$J$3:$J$45,J$4,Rewards!$K$3:$K$45,J22)+SUMIFS(Rewards!$L$3:$L$45,Rewards!$J$3:$J$45,K$4,Rewards!$K$3:$K$45,K22)+SUMIFS(Rewards!$L$3:$L$45,Rewards!$J$3:$J$45,L$4,Rewards!$K$3:$K$45,L22)+SUMIFS(Rewards!$L$3:$L$45,Rewards!$J$3:$J$45,M$4,Rewards!$K$3:$K$45,M22)+SUMIFS(Rewards!$L$3:$L$45,Rewards!$J$3:$J$45,N$4,Rewards!$K$3:$K$45,N22) -> 70 | P22: =IF($O22<=20,0,IF($O22<=45,2750,IF($O22<=50,3750,IF($O22<=65,6500,IF($O22<=70,7500,""))))) -> 7500 | T22: Option 18 | U22: =COUNTIF($B22:$N22,U$4) -> 4 | V22: =COUNTIF($B22:$N22,V$4) -> 5 | W22: =COUNTIF($B22:$N22,W$4) -> 1 | X22: =COUNTIF($B22:$N22,X$4) -> 0 | Y22: =COUNTIF($B22:$N22,Y$4) -> 0 | Z22: =COUNTIF($B22:$N22,Z$4) -> 0 | AA22: =COUNTIF($B22:$N22,AA$4) -> 3
A23: DT/ORIGIN Hunt | B23: Void | C23: Void | D23: Origin | E23: Void | F23: DT | G23: Origin | H23: Origin | I23: Origin | J23: Origin | K23: DT | L23: DT | M23: Origin | N23: DT | O23: =SUMIFS(Rewards!$L$3:$L$45,Rewards!$J$3:$J$45,B$4,Rewards!$K$3:$K$45,B23)+SUMIFS(Rewards!$L$3:$L$45,Rewards!$J$3:$J$45,C$4,Rewards!$K$3:$K$45,C23)+SUMIFS(Rewards!$L$3:$L$45,Rewards!$J$3:$J$45,D$4,Rewards!$K$3:$K$45,D23)+SUMIFS(Rewards!$L$3:$L$45,Rewards!$J$3:$J$45,E$4,Rewards!$K$3:$K$45,E23)+SUMIFS(Rewards!$L$3:$L$45,Rewards!$J$3:$J$45,F$4,Rewards!$K$3:$K$45,F23)+SUMIFS(Rewards!$L$3:$L$45,Rewards!$J$3:$J$45,G$4,Rewards!$K$3:$K$45,G23)+SUMIFS(Rewards!$L$3:$L$45,Rewards!$J$3:$J$45,H$4,Rewards!$K$3:$K$45,H23)+SUMIFS(Rewards!$L$3:$L$45,Rewards!$J$3:$J$45,I$4,Rewards!$K$3:$K$45,I23)+SUMIFS(Rewards!$L$3:$L$45,Rewards!$J$3:$J$45,J$4,Rewards!$K$3:$K$45,J23)+SUMIFS(Rewards!$L$3:$L$45,Rewards!$J$3:$J$45,K$4,Rewards!$K$3:$K$45,K23)+SUMIFS(Rewards!$L$3:$L$45,Rewards!$J$3:$J$45,L$4,Rewards!$K$3:$K$45,L23)+SUMIFS(Rewards!$L$3:$L$45,Rewards!$J$3:$J$45,M$4,Rewards!$K$3:$K$45,M23)+SUMIFS(Rewards!$L$3:$L$45,Rewards!$J$3:$J$45,N$4,Rewards!$K$3:$K$45,N23) -> 65 | P23: =IF($O23<=20,0,IF($O23<=45,2750,IF($O23<=50,3750,IF($O23<=65,6500,IF($O23<=70,7500,""))))) -> 6500 | T23: Option 19 | U23: =COUNTIF($B23:$N23,U$4) -> 3 | V23: =COUNTIF($B23:$N23,V$4) -> 6 | W23: =COUNTIF($B23:$N23,W$4) -> 4 | X23: =COUNTIF($B23:$N23,X$4) -> 0 | Y23: =COUNTIF($B23:$N23,Y$4) -> 0 | Z23: =COUNTIF($B23:$N23,Z$4) -> 0 | AA23: =COUNTIF($B23:$N23,AA$4) -> 0
A24: Option 20 | O24: =SUMIFS(Rewards!$L$3:$L$45,Rewards!$J$3:$J$45,B$4,Rewards!$K$3:$K$45,B24)+SUMIFS(Rewards!$L$3:$L$45,Rewards!$J$3:$J$45,C$4,Rewards!$K$3:$K$45,C24)+SUMIFS(Rewards!$L$3:$L$45,Rewards!$J$3:$J$45,D$4,Rewards!$K$3:$K$45,D24)+SUMIFS(Rewards!$L$3:$L$45,Rewards!$J$3:$J$45,E$4,Rewards!$K$3:$K$45,E24)+SUMIFS(Rewards!$L$3:$L$45,Rewards!$J$3:$J$45,F$4,Rewards!$K$3:$K$45,F24)+SUMIFS(Rewards!$L$3:$L$45,Rewards!$J$3:$J$45,G$4,Rewards!$K$3:$K$45,G24)+SUMIFS(Rewards!$L$3:$L$45,Rewards!$J$3:$J$45,H$4,Rewards!$K$3:$K$45,H24)+SUMIFS(Rewards!$L$3:$L$45,Rewards!$J$3:$J$45,I$4,Rewards!$K$3:$K$45,I24)+SUMIFS(Rewards!$L$3:$L$45,Rewards!$J$3:$J$45,J$4,Rewards!$K$3:$K$45,J24)+SUMIFS(Rewards!$L$3:$L$45,Rewards!$J$3:$J$45,K$4,Rewards!$K$3:$K$45,K24)+SUMIFS(Rewards!$L$3:$L$45,Rewards!$J$3:$J$45,L$4,Rewards!$K$3:$K$45,L24)+SUMIFS(Rewards!$L$3:$L$45,Rewards!$J$3:$J$45,M$4,Rewards!$K$3:$K$45,M24)+SUMIFS(Rewards!$L$3:$L$45,Rewards!$J$3:$J$45,N$4,Rewards!$K$3:$K$45,N24) -> 0 | P24: =IF($O24<=20,0,IF($O24<=45,2750,IF($O24<=50,3750,IF($O24<=65,6500,IF($O24<=70,7500,""))))) -> 0 | T24: Option 20 | U24: =COUNTIF($B24:$N24,U$4) -> 0 | V24: =COUNTIF($B24:$N24,V$4) -> 0 | W24: =COUNTIF($B24:$N24,W$4) -> 0 | X24: =COUNTIF($B24:$N24,X$4) -> 0 | Y24: =COUNTIF($B24:$N24,Y$4) -> 0 | Z24: =COUNTIF($B24:$N24,Z$4) -> 0 | AA24: =COUNTIF($B24:$N24,AA$4) -> 0
A25: Option 21 | O25: =SUMIFS(Rewards!$L$3:$L$45,Rewards!$J$3:$J$45,B$4,Rewards!$K$3:$K$45,B25)+SUMIFS(Rewards!$L$3:$L$45,Rewards!$J$3:$J$45,C$4,Rewards!$K$3:$K$45,C25)+SUMIFS(Rewards!$L$3:$L$45,Rewards!$J$3:$J$45,D$4,Rewards!$K$3:$K$45,D25)+SUMIFS(Rewards!$L$3:$L$45,Rewards!$J$3:$J$45,E$4,Rewards!$K$3:$K$45,E25)+SUMIFS(Rewards!$L$3:$L$45,Rewards!$J$3:$J$45,F$4,Rewards!$K$3:$K$45,F25)+SUMIFS(Rewards!$L$3:$L$45,Rewards!$J$3:$J$45,G$4,Rewards!$K$3:$K$45,G25)+SUMIFS(Rewards!$L$3:$L$45,Rewards!$J$3:$J$45,H$4,Rewards!$K$3:$K$45,H25)+SUMIFS(Rewards!$L$3:$L$45,Rewards!$J$3:$J$45,I$4,Rewards!$K$3:$K$45,I25)+SUMIFS(Rewards!$L$3:$L$45,Rewards!$J$3:$J$45,J$4,Rewards!$K$3:$K$45,J25)+SUMIFS(Rewards!$L$3:$L$45,Rewards!$J$3:$J$45,K$4,Rewards!$K$3:$K$45,K25)+SUMIFS(Rewards!$L$3:$L$45,Rewards!$J$3:$J$45,L$4,Rewards!$K$3:$K$45,L25)+SUMIFS(Rewards!$L$3:$L$45,Rewards!$J$3:$J$45,M$4,Rewards!$K$3:$K$45,M25)+SUMIFS(Rewards!$L$3:$L$45,Rewards!$J$3:$J$45,N$4,Rewards!$K$3:$K$45,N25) -> 0 | P25: =IF($O25<=20,0,IF($O25<=45,2750,IF($O25<=50,3750,IF($O25<=65,6500,IF($O25<=70,7500,""))))) -> 0 | T25: Option 21 | U25: =COUNTIF($B25:$N25,U$4) -> 0 | V25: =COUNTIF($B25:$N25,V$4) -> 0 | W25: =COUNTIF($B25:$N25,W$4) -> 0 | X25: =COUNTIF($B25:$N25,X$4) -> 0 | Y25: =COUNTIF($B25:$N25,Y$4) -> 0 | Z25: =COUNTIF($B25:$N25,Z$4) -> 0 | AA25: =COUNTIF($B25:$N25,AA$4) -> 0
A26: Option 22 | O26: =SUMIFS(Rewards!$L$3:$L$45,Rewards!$J$3:$J$45,B$4,Rewards!$K$3:$K$45,B26)+SUMIFS(Rewards!$L$3:$L$45,Rewards!$J$3:$J$45,C$4,Rewards!$K$3:$K$45,C26)+SUMIFS(Rewards!$L$3:$L$45,Rewards!$J$3:$J$45,D$4,Rewards!$K$3:$K$45,D26)+SUMIFS(Rewards!$L$3:$L$45,Rewards!$J$3:$J$45,E$4,Rewards!$K$3:$K$45,E26)+SUMIFS(Rewards!$L$3:$L$45,Rewards!$J$3:$J$45,F$4,Rewards!$K$3:$K$45,F26)+SUMIFS(Rewards!$L$3:$L$45,Rewards!$J$3:$J$45,G$4,Rewards!$K$3:$K$45,G26)+SUMIFS(Rewards!$L$3:$L$45,Rewards!$J$3:$J$45,H$4,Rewards!$K$3:$K$45,H26)+SUMIFS(Rewards!$L$3:$L$45,Rewards!$J$3:$J$45,I$4,Rewards!$K$3:$K$45,I26)+SUMIFS(Rewards!$L$3:$L$45,Rewards!$J$3:$J$45,J$4,Rewards!$K$3:$K$45,J26)+SUMIFS(Rewards!$L$3:$L$45,Rewards!$J$3:$J$45,K$4,Rewards!$K$3:$K$45,K26)+SUMIFS(Rewards!$L$3:$L$45,Rewards!$J$3:$J$45,L$4,Rewards!$K$3:$K$45,L26)+SUMIFS(Rewards!$L$3:$L$45,Rewards!$J$3:$J$45,M$4,Rewards!$K$3:$K$45,M26)+SUMIFS(Rewards!$L$3:$L$45,Rewards!$J$3:$J$45,N$4,Rewards!$K$3:$K$45,N26) -> 0 | P26: =IF($O26<=20,0,IF($O26<=45,2750,IF($O26<=50,3750,IF($O26<=65,6500,IF($O26<=70,7500,""))))) -> 0 | T26: Option 22 | U26: =COUNTIF($B26:$N26,U$4) -> 0 | V26: =COUNTIF($B26:$N26,V$4) -> 0 | W26: =COUNTIF($B26:$N26,W$4) -> 0 | X26: =COUNTIF($B26:$N26,X$4) -> 0 | Y26: =COUNTIF($B26:$N26,Y$4) -> 0 | Z26: =COUNTIF($B26:$N26,Z$4) -> 0 | AA26: =COUNTIF($B26:$N26,AA$4) -> 0
A27: Option 23 | O27: =SUMIFS(Rewards!$L$3:$L$45,Rewards!$J$3:$J$45,B$4,Rewards!$K$3:$K$45,B27)+SUMIFS(Rewards!$L$3:$L$45,Rewards!$J$3:$J$45,C$4,Rewards!$K$3:$K$45,C27)+SUMIFS(Rewards!$L$3:$L$45,Rewards!$J$3:$J$45,D$4,Rewards!$K$3:$K$45,D27)+SUMIFS(Rewards!$L$3:$L$45,Rewards!$J$3:$J$45,E$4,Rewards!$K$3:$K$45,E27)+SUMIFS(Rewards!$L$3:$L$45,Rewards!$J$3:$J$45,F$4,Rewards!$K$3:$K$45,F27)+SUMIFS(Rewards!$L$3:$L$45,Rewards!$J$3:$J$45,G$4,Rewards!$K$3:$K$45,G27)+SUMIFS(Rewards!$L$3:$L$45,Rewards!$J$3:$J$45,H$4,Rewards!$K$3:$K$45,H27)+SUMIFS(Rewards!$L$3:$L$45,Rewards!$J$3:$J$45,I$4,Rewards!$K$3:$K$45,I27)+SUMIFS(Rewards!$L$3:$L$45,Rewards!$J$3:$J$45,J$4,Rewards!$K$3:$K$45,J27)+SUMIFS(Rewards!$L$3:$L$45,Rewards!$J$3:$J$45,K$4,Rewards!$K$3:$K$45,K27)+SUMIFS(Rewards!$L$3:$L$45,Rewards!$J$3:$J$45,L$4,Rewards!$K$3:$K$45,L27)+SUMIFS(Rewards!$L$3:$L$45,Rewards!$J$3:$J$45,M$4,Rewards!$K$3:$K$45,M27)+SUMIFS(Rewards!$L$3:$L$45,Rewards!$J$3:$J$45,N$4,Rewards!$K$3:$K$45,N27) -> 0 | P27: =IF($O27<=20,0,IF($O27<=45,2750,IF($O27<=50,3750,IF($O27<=65,6500,IF($O27<=70,7500,""))))) -> 0 | T27: Option 23 | U27: =COUNTIF($B27:$N27,U$4) -> 0 | V27: =COUNTIF($B27:$N27,V$4) -> 0 | W27: =COUNTIF($B27:$N27,W$4) -> 0 | X27: =COUNTIF($B27:$N27,X$4) -> 0 | Y27: =COUNTIF($B27:$N27,Y$4) -> 0 | Z27: =COUNTIF($B27:$N27,Z$4) -> 0 | AA27: =COUNTIF($B27:$N27,AA$4) -> 0
A28: Option 24 | O28: =SUMIFS(Rewards!$L$3:$L$45,Rewards!$J$3:$J$45,B$4,Rewards!$K$3:$K$45,B28)+SUMIFS(Rewards!$L$3:$L$45,Rewards!$J$3:$J$45,C$4,Rewards!$K$3:$K$45,C28)+SUMIFS(Rewards!$L$3:$L$45,Rewards!$J$3:$J$45,D$4,Rewards!$K$3:$K$45,D28)+SUMIFS(Rewards!$L$3:$L$45,Rewards!$J$3:$J$45,E$4,Rewards!$K$3:$K$45,E28)+SUMIFS(Rewards!$L$3:$L$45,Rewards!$J$3:$J$45,F$4,Rewards!$K$3:$K$45,F28)+SUMIFS(Rewards!$L$3:$L$45,Rewards!$J$3:$J$45,G$4,Rewards!$K$3:$K$45,G28)+SUMIFS(Rewards!$L$3:$L$45,Rewards!$J$3:$J$45,H$4,Rewards!$K$3:$K$45,H28)+SUMIFS(Rewards!$L$3:$L$45,Rewards!$J$3:$J$45,I$4,Rewards!$K$3:$K$45,I28)+SUMIFS(Rewards!$L$3:$L$45,Rewards!$J$3:$J$45,J$4,Rewards!$K$3:$K$45,J28)+SUMIFS(Rewards!$L$3:$L$45,Rewards!$J$3:$J$45,K$4,Rewards!$K$3:$K$45,K28)+SUMIFS(Rewards!$L$3:$L$45,Rewards!$J$3:$J$45,L$4,Rewards!$K$3:$K$45,L28)+SUMIFS(Rewards!$L$3:$L$45,Rewards!$J$3:$J$45,M$4,Rewards!$K$3:$K$45,M28)+SUMIFS(Rewards!$L$3:$L$45,Rewards!$J$3:$J$45,N$4,Rewards!$K$3:$K$45,N28) -> 0 | P28: =IF($O28<=20,0,IF($O28<=45,2750,IF($O28<=50,3750,IF($O28<=65,6500,IF($O28<=70,7500,""))))) -> 0 | T28: Option 24 | U28: =COUNTIF($B28:$N28,U$4) -> 0 | V28: =COUNTIF($B28:$N28,V$4) -> 0 | W28: =COUNTIF($B28:$N28,W$4) -> 0 | X28: =COUNTIF($B28:$N28,X$4) -> 0 | Y28: =COUNTIF($B28:$N28,Y$4) -> 0 | Z28: =COUNTIF($B28:$N28,Z$4) -> 0 | AA28: =COUNTIF($B28:$N28,AA$4) -> 0
A29: Option 25 | O29: =SUMIFS(Rewards!$L$3:$L$45,Rewards!$J$3:$J$45,B$4,Rewards!$K$3:$K$45,B29)+SUMIFS(Rewards!$L$3:$L$45,Rewards!$J$3:$J$45,C$4,Rewards!$K$3:$K$45,C29)+SUMIFS(Rewards!$L$3:$L$45,Rewards!$J$3:$J$45,D$4,Rewards!$K$3:$K$45,D29)+SUMIFS(Rewards!$L$3:$L$45,Rewards!$J$3:$J$45,E$4,Rewards!$K$3:$K$45,E29)+SUMIFS(Rewards!$L$3:$L$45,Rewards!$J$3:$J$45,F$4,Rewards!$K$3:$K$45,F29)+SUMIFS(Rewards!$L$3:$L$45,Rewards!$J$3:$J$45,G$4,Rewards!$K$3:$K$45,G29)+SUMIFS(Rewards!$L$3:$L$45,Rewards!$J$3:$J$45,H$4,Rewards!$K$3:$K$45,H29)+SUMIFS(Rewards!$L$3:$L$45,Rewards!$J$3:$J$45,I$4,Rewards!$K$3:$K$45,I29)+SUMIFS(Rewards!$L$3:$L$45,Rewards!$J$3:$J$45,J$4,Rewards!$K$3:$K$45,J29)+SUMIFS(Rewards!$L$3:$L$45,Rewards!$J$3:$J$45,K$4,Rewards!$K$3:$K$45,K29)+SUMIFS(Rewards!$L$3:$L$45,Rewards!$J$3:$J$45,L$4,Rewards!$K$3:$K$45,L29)+SUMIFS(Rewards!$L$3:$L$45,Rewards!$J$3:$J$45,M$4,Rewards!$K$3:$K$45,M29)+SUMIFS(Rewards!$L$3:$L$45,Rewards!$J$3:$J$45,N$4,Rewards!$K$3:$K$45,N29) -> 0 | P29: =IF($O29<=20,0,IF($O29<=45,2750,IF($O29<=50,3750,IF($O29<=65,6500,IF($O29<=70,7500,""))))) -> 0 | T29: Option 25 | U29: =COUNTIF($B29:$N29,U$4) -> 0 | V29: =COUNTIF($B29:$N29,V$4) -> 0 | W29: =COUNTIF($B29:$N29,W$4) -> 0 | X29: =COUNTIF($B29:$N29,X$4) -> 0 | Y29: =COUNTIF($B29:$N29,Y$4) -> 0 | Z29: =COUNTIF($B29:$N29,Z$4) -> 0 | AA29: =COUNTIF($B29:$N29,AA$4) -> 0
A30: Option 26 | O30: =SUMIFS(Rewards!$L$3:$L$45,Rewards!$J$3:$J$45,B$4,Rewards!$K$3:$K$45,B30)+SUMIFS(Rewards!$L$3:$L$45,Rewards!$J$3:$J$45,C$4,Rewards!$K$3:$K$45,C30)+SUMIFS(Rewards!$L$3:$L$45,Rewards!$J$3:$J$45,D$4,Rewards!$K$3:$K$45,D30)+SUMIFS(Rewards!$L$3:$L$45,Rewards!$J$3:$J$45,E$4,Rewards!$K$3:$K$45,E30)+SUMIFS(Rewards!$L$3:$L$45,Rewards!$J$3:$J$45,F$4,Rewards!$K$3:$K$45,F30)+SUMIFS(Rewards!$L$3:$L$45,Rewards!$J$3:$J$45,G$4,Rewards!$K$3:$K$45,G30)+SUMIFS(Rewards!$L$3:$L$45,Rewards!$J$3:$J$45,H$4,Rewards!$K$3:$K$45,H30)+SUMIFS(Rewards!$L$3:$L$45,Rewards!$J$3:$J$45,I$4,Rewards!$K$3:$K$45,I30)+SUMIFS(Rewards!$L$3:$L$45,Rewards!$J$3:$J$45,J$4,Rewards!$K$3:$K$45,J30)+SUMIFS(Rewards!$L$3:$L$45,Rewards!$J$3:$J$45,K$4,Rewards!$K$3:$K$45,K30)+SUMIFS(Rewards!$L$3:$L$45,Rewards!$J$3:$J$45,L$4,Rewards!$K$3:$K$45,L30)+SUMIFS(Rewards!$L$3:$L$45,Rewards!$J$3:$J$45,M$4,Rewards!$K$3:$K$45,M30)+SUMIFS(Rewards!$L$3:$L$45,Rewards!$J$3:$J$45,N$4,Rewards!$K$3:$K$45,N30) -> 0 | P30: =IF($O30<=20,0,IF($O30<=45,2750,IF($O30<=50,3750,IF($O30<=65,6500,IF($O30<=70,7500,""))))) -> 0 | T30: Option 26 | U30: =COUNTIF($B30:$N30,U$4) -> 0 | V30: =COUNTIF($B30:$N30,V$4) -> 0 | W30: =COUNTIF($B30:$N30,W$4) -> 0 | X30: =COUNTIF($B30:$N30,X$4) -> 0 | Y30: =COUNTIF($B30:$N30,Y$4) -> 0 | Z30: =COUNTIF($B30:$N30,Z$4) -> 0 | AA30: =COUNTIF($B30:$N30,AA$4) -> 0
A31: Option 27 | O31: =SUMIFS(Rewards!$L$3:$L$45,Rewards!$J$3:$J$45,B$4,Rewards!$K$3:$K$45,B31)+SUMIFS(Rewards!$L$3:$L$45,Rewards!$J$3:$J$45,C$4,Rewards!$K$3:$K$45,C31)+SUMIFS(Rewards!$L$3:$L$45,Rewards!$J$3:$J$45,D$4,Rewards!$K$3:$K$45,D31)+SUMIFS(Rewards!$L$3:$L$45,Rewards!$J$3:$J$45,E$4,Rewards!$K$3:$K$45,E31)+SUMIFS(Rewards!$L$3:$L$45,Rewards!$J$3:$J$45,F$4,Rewards!$K$3:$K$45,F31)+SUMIFS(Rewards!$L$3:$L$45,Rewards!$J$3:$J$45,G$4,Rewards!$K$3:$K$45,G31)+SUMIFS(Rewards!$L$3:$L$45,Rewards!$J$3:$J$45,H$4,Rewards!$K$3:$K$45,H31)+SUMIFS(Rewards!$L$3:$L$45,Rewards!$J$3:$J$45,I$4,Rewards!$K$3:$K$45,I31)+SUMIFS(Rewards!$L$3:$L$45,Rewards!$J$3:$J$45,J$4,Rewards!$K$3:$K$45,J31)+SUMIFS(Rewards!$L$3:$L$45,Rewards!$J$3:$J$45,K$4,Rewards!$K$3:$K$45,K31)+SUMIFS(Rewards!$L$3:$L$45,Rewards!$J$3:$J$45,L$4,Rewards!$K$3:$K$45,L31)+SUMIFS(Rewards!$L$3:$L$45,Rewards!$J$3:$J$45,M$4,Rewards!$K$3:$K$45,M31)+SUMIFS(Rewards!$L$3:$L$45,Rewards!$J$3:$J$45,N$4,Rewards!$K$3:$K$45,N31) -> 0 | P31: =IF($O31<=20,0,IF($O31<=45,2750,IF($O31<=50,3750,IF($O31<=65,6500,IF($O31<=70,7500,""))))) -> 0 | T31: Option 27 | U31: =COUNTIF($B31:$N31,U$4) -> 0 | V31: =COUNTIF($B31:$N31,V$4) -> 0 | W31: =COUNTIF($B31:$N31,W$4) -> 0 | X31: =COUNTIF($B31:$N31,X$4) -> 0 | Y31: =COUNTIF($B31:$N31,Y$4) -> 0 | Z31: =COUNTIF($B31:$N31,Z$4) -> 0 | AA31: =COUNTIF($B31:$N31,AA$4) -> 0
A32: Option 28 | O32: =SUMIFS(Rewards!$L$3:$L$45,Rewards!$J$3:$J$45,B$4,Rewards!$K$3:$K$45,B32)+SUMIFS(Rewards!$L$3:$L$45,Rewards!$J$3:$J$45,C$4,Rewards!$K$3:$K$45,C32)+SUMIFS(Rewards!$L$3:$L$45,Rewards!$J$3:$J$45,D$4,Rewards!$K$3:$K$45,D32)+SUMIFS(Rewards!$L$3:$L$45,Rewards!$J$3:$J$45,E$4,Rewards!$K$3:$K$45,E32)+SUMIFS(Rewards!$L$3:$L$45,Rewards!$J$3:$J$45,F$4,Rewards!$K$3:$K$45,F32)+SUMIFS(Rewards!$L$3:$L$45,Rewards!$J$3:$J$45,G$4,Rewards!$K$3:$K$45,G32)+SUMIFS(Rewards!$L$3:$L$45,Rewards!$J$3:$J$45,H$4,Rewards!$K$3:$K$45,H32)+SUMIFS(Rewards!$L$3:$L$45,Rewards!$J$3:$J$45,I$4,Rewards!$K$3:$K$45,I32)+SUMIFS(Rewards!$L$3:$L$45,Rewards!$J$3:$J$45,J$4,Rewards!$K$3:$K$45,J32)+SUMIFS(Rewards!$L$3:$L$45,Rewards!$J$3:$J$45,K$4,Rewards!$K$3:$K$45,K32)+SUMIFS(Rewards!$L$3:$L$45,Rewards!$J$3:$J$45,L$4,Rewards!$K$3:$K$45,L32)+SUMIFS(Rewards!$L$3:$L$45,Rewards!$J$3:$J$45,M$4,Rewards!$K$3:$K$45,M32)+SUMIFS(Rewards!$L$3:$L$45,Rewards!$J$3:$J$45,N$4,Rewards!$K$3:$K$45,N32) -> 0 | P32: =IF($O32<=20,0,IF($O32<=45,2750,IF($O32<=50,3750,IF($O32<=65,6500,IF($O32<=70,7500,""))))) -> 0 | T32: Option 28 | U32: =COUNTIF($B32:$N32,U$4) -> 0 | V32: =COUNTIF($B32:$N32,V$4) -> 0 | W32: =COUNTIF($B32:$N32,W$4) -> 0 | X32: =COUNTIF($B32:$N32,X$4) -> 0 | Y32: =COUNTIF($B32:$N32,Y$4) -> 0 | Z32: =COUNTIF($B32:$N32,Z$4) -> 0 | AA32: =COUNTIF($B32:$N32,AA$4) -> 0
A33: Option 29 | O33: =SUMIFS(Rewards!$L$3:$L$45,Rewards!$J$3:$J$45,B$4,Rewards!$K$3:$K$45,B33)+SUMIFS(Rewards!$L$3:$L$45,Rewards!$J$3:$J$45,C$4,Rewards!$K$3:$K$45,C33)+SUMIFS(Rewards!$L$3:$L$45,Rewards!$J$3:$J$45,D$4,Rewards!$K$3:$K$45,D33)+SUMIFS(Rewards!$L$3:$L$45,Rewards!$J$3:$J$45,E$4,Rewards!$K$3:$K$45,E33)+SUMIFS(Rewards!$L$3:$L$45,Rewards!$J$3:$J$45,F$4,Rewards!$K$3:$K$45,F33)+SUMIFS(Rewards!$L$3:$L$45,Rewards!$J$3:$J$45,G$4,Rewards!$K$3:$K$45,G33)+SUMIFS(Rewards!$L$3:$L$45,Rewards!$J$3:$J$45,H$4,Rewards!$K$3:$K$45,H33)+SUMIFS(Rewards!$L$3:$L$45,Rewards!$J$3:$J$45,I$4,Rewards!$K$3:$K$45,I33)+SUMIFS(Rewards!$L$3:$L$45,Rewards!$J$3:$J$45,J$4,Rewards!$K$3:$K$45,J33)+SUMIFS(Rewards!$L$3:$L$45,Rewards!$J$3:$J$45,K$4,Rewards!$K$3:$K$45,K33)+SUMIFS(Rewards!$L$3:$L$45,Rewards!$J$3:$J$45,L$4,Rewards!$K$3:$K$45,L33)+SUMIFS(Rewards!$L$3:$L$45,Rewards!$J$3:$J$45,M$4,Rewards!$K$3:$K$45,M33)+SUMIFS(Rewards!$L$3:$L$45,Rewards!$J$3:$J$45,N$4,Rewards!$K$3:$K$45,N33) -> 0 | P33: =IF($O33<=20,0,IF($O33<=45,2750,IF($O33<=50,3750,IF($O33<=65,6500,IF($O33<=70,7500,""))))) -> 0 | T33: Option 29 | U33: =COUNTIF($B33:$N33,U$4) -> 0 | V33: =COUNTIF($B33:$N33,V$4) -> 0 | W33: =COUNTIF($B33:$N33,W$4) -> 0 | X33: =COUNTIF($B33:$N33,X$4) -> 0 | Y33: =COUNTIF($B33:$N33,Y$4) -> 0 | Z33: =COUNTIF($B33:$N33,Z$4) -> 0 | AA33: =COUNTIF($B33:$N33,AA$4) -> 0
A34: Option 30 | O34: =SUMIFS(Rewards!$L$3:$L$45,Rewards!$J$3:$J$45,B$4,Rewards!$K$3:$K$45,B34)+SUMIFS(Rewards!$L$3:$L$45,Rewards!$J$3:$J$45,C$4,Rewards!$K$3:$K$45,C34)+SUMIFS(Rewards!$L$3:$L$45,Rewards!$J$3:$J$45,D$4,Rewards!$K$3:$K$45,D34)+SUMIFS(Rewards!$L$3:$L$45,Rewards!$J$3:$J$45,E$4,Rewards!$K$3:$K$45,E34)+SUMIFS(Rewards!$L$3:$L$45,Rewards!$J$3:$J$45,F$4,Rewards!$K$3:$K$45,F34)+SUMIFS(Rewards!$L$3:$L$45,Rewards!$J$3:$J$45,G$4,Rewards!$K$3:$K$45,G34)+SUMIFS(Rewards!$L$3:$L$45,Rewards!$J$3:$J$45,H$4,Rewards!$K$3:$K$45,H34)+SUMIFS(Rewards!$L$3:$L$45,Rewards!$J$3:$J$45,I$4,Rewards!$K$3:$K$45,I34)+SUMIFS(Rewards!$L$3:$L$45,Rewards!$J$3:$J$45,J$4,Rewards!$K$3:$K$45,J34)+SUMIFS(Rewards!$L$3:$L$45,Rewards!$J$3:$J$45,K$4,Rewards!$K$3:$K$45,K34)+SUMIFS(Rewards!$L$3:$L$45,Rewards!$J$3:$J$45,L$4,Rewards!$K$3:$K$45,L34)+SUMIFS(Rewards!$L$3:$L$45,Rewards!$J$3:$J$45,M$4,Rewards!$K$3:$K$45,M34)+SUMIFS(Rewards!$L$3:$L$45,Rewards!$J$3:$J$45,N$4,Rewards!$K$3:$K$45,N34) -> 0 | P34: =IF($O34<=20,0,IF($O34<=45,2750,IF($O34<=50,3750,IF($O34<=65,6500,IF($O34<=70,7500,""))))) -> 0 | T34: Option 30 | U34: =COUNTIF($B34:$N34,U$4) -> 0 | V34: =COUNTIF($B34:$N34,V$4) -> 0 | W34: =COUNTIF($B34:$N34,W$4) -> 0 | X34: =COUNTIF($B34:$N34,X$4) -> 0 | Y34: =COUNTIF($B34:$N34,Y$4) -> 0 | Z34: =COUNTIF($B34:$N34,Z$4) -> 0 | AA34: =COUNTIF($B34:$N34,AA$4) -> 0
A35: Option 31 | O35: =SUMIFS(Rewards!$L$3:$L$45,Rewards!$J$3:$J$45,B$4,Rewards!$K$3:$K$45,B35)+SUMIFS(Rewards!$L$3:$L$45,Rewards!$J$3:$J$45,C$4,Rewards!$K$3:$K$45,C35)+SUMIFS(Rewards!$L$3:$L$45,Rewards!$J$3:$J$45,D$4,Rewards!$K$3:$K$45,D35)+SUMIFS(Rewards!$L$3:$L$45,Rewards!$J$3:$J$45,E$4,Rewards!$K$3:$K$45,E35)+SUMIFS(Rewards!$L$3:$L$45,Rewards!$J$3:$J$45,F$4,Rewards!$K$3:$K$45,F35)+SUMIFS(Rewards!$L$3:$L$45,Rewards!$J$3:$J$45,G$4,Rewards!$K$3:$K$45,G35)+SUMIFS(Rewards!$L$3:$L$45,Rewards!$J$3:$J$45,H$4,Rewards!$K$3:$K$45,H35)+SUMIFS(Rewards!$L$3:$L$45,Rewards!$J$3:$J$45,I$4,Rewards!$K$3:$K$45,I35)+SUMIFS(Rewards!$L$3:$L$45,Rewards!$J$3:$J$45,J$4,Rewards!$K$3:$K$45,J35)+SUMIFS(Rewards!$L$3:$L$45,Rewards!$J$3:$J$45,K$4,Rewards!$K$3:$K$45,K35)+SUMIFS(Rewards!$L$3:$L$45,Rewards!$J$3:$J$45,L$4,Rewards!$K$3:$K$45,L35)+SUMIFS(Rewards!$L$3:$L$45,Rewards!$J$3:$J$45,M$4,Rewards!$K$3:$K$45,M35)+SUMIFS(Rewards!$L$3:$L$45,Rewards!$J$3:$J$45,N$4,Rewards!$K$3:$K$45,N35) -> 0 | P35: =IF($O35<=20,0,IF($O35<=45,2750,IF($O35<=50,3750,IF($O35<=65,6500,IF($O35<=70,7500,""))))) -> 0 | T35: Option 31 | U35: =COUNTIF($B35:$N35,U$4) -> 0 | V35: =COUNTIF($B35:$N35,V$4) -> 0 | W35: =COUNTIF($B35:$N35,W$4) -> 0 | X35: =COUNTIF($B35:$N35,X$4) -> 0 | Y35: =COUNTIF($B35:$N35,Y$4) -> 0 | Z35: =COUNTIF($B35:$N35,Z$4) -> 0 | AA35: =COUNTIF($B35:$N35,AA$4) -> 0
... A104: Option 100 | O104: =SUMIFS(Rewards!$L$3:$L$45,Rewards!$J$3:$J$45,B$4,Rewards!$K$3:$K$45,B104)+SUMIFS(Rewards!$L$3:$L$45,Rewards!$J$3:$J$45,C$4,Rewards!$K$3:$K$45,C104)+SUMIFS(Rewards!$L$3:$L$45,Rewards!$J$3:$J$45,D$4,Rewards!$K$3:$K$45,D104)+SUMIFS(Rewards!$L$3:$L$45,Rewards!$J$3:$J$45,E$4,Rewards!$K$3:$K$45,E104)+SUMIFS(Rewards!$L$3:$L$45,Rewards!$J$3:$J$45,F$4,Rewards!$K$3:$K$45,F104)+SUMIFS(Rewards!$L$3:$L$45,Rewards!$J$3:$J$45,G$4,Rewards!$K$3:$K$45,G104)+SUMIFS(Rewards!$L$3:$L$45,Rewards!$J$3:$J$45,H$4,Rewards!$K$3:$K$45,H104)+SUMIFS(Rewards!$L$3:$L$45,Rewards!$J$3:$J$45,I$4,Rewards!$K$3:$K$45,I104)+SUMIFS(Rewards!$L$3:$L$45,Rewards!$J$3:$J$45,J$4,Rewards!$K$3:$K$45,J104)+SUMIFS(Rewards!$L$3:$L$45,Rewards!$J$3:$J$45,K$4,Rewards!$K$3:$K$45,K104)+SUMIFS(Rewards!$L$3:$L$45,Rewards!$J$3:$J$45,L$4,Rewards!$K$3:$K$45,L104)+SUMIFS(Rewards!$L$3:$L$45,Rewards!$J$3:$J$45,M$4,Rewards!$K$3:$K$45,M104)+SUMIFS(Rewards!$L$3:$L$45,Rewards!$J$3:$J$45,N$4,Rewards!$K$3:$K$45,N104) -> 0 | P104: =IF($O104<=20,0,IF($O104<=45,2750,IF($O104<=50,3750,IF($O104<=65,6500,IF($O104<=70,7500,""))))) -> 0 | T104: Option 100 | U104: =COUNTIF($B104:$N104,U$4) -> 0 | V104: =COUNTIF($B104:$N104,V$4) -> 0 | W104: =COUNTIF($B104:$N104,W$4) -> 0 | X104: =COUNTIF($B104:$N104,X$4) -> 0 | Y104: =COUNTIF($B104:$N104,Y$4) -> 0 | Z104: =COUNTIF($B104:$N104,Z$4) -> 0 | AA104: =COUNTIF($B104:$N104,AA$4) -> 0

Sheet Cases
A1: Cases / Combo Planner
A2: Choose options from Sheet 2 and set the quantity. The sheet adds all rewards together and sums the SG cost of each selected option multiplied by Qty. Example: Case 1 uses Option 3 three times.
A3: Case | B3: Option slots | L3: Costs | M3: Cumulative Rewards
A4: Case | B4: Option 1 | C4: weeks | D4: Option 2 | E4: weeks | F4: Option 3 | G4: weeks | H4: Option 4 | I4: weeks | J4: Option 5 | K4: weeks | L4: Total SG Cost | M4: Void | N4: Origin | O4: DT | P4: Star Soul | Q4: Artifacts | R4: Origin Artifacts | S4: Grim
A5: 6 week Case 1 | B5: Balanced 45 | C5: 6 | L5: =SUM(IFERROR(N($C5)*N(INDEX(Options!$P$5:$P$104,MATCH($B5,Options!$A$5:$A$104,0))),0),IFERROR(N($E5)*N(INDEX(Options!$P$5:$P$104,MATCH($D5,Options!$A$5:$A$104,0))),0),IFERROR(N($G5)*N(INDEX(Options!$P$5:$P$104,MATCH($F5,Options!$A$5:$A$104,0))),0),IFERROR(N($I5)*N(INDEX(Options!$P$5:$P$104,MATCH($H5,Options!$A$5:$A$104,0))),0),IFERROR(N($K5)*N(INDEX(Options!$P$5:$P$104,MATCH($J5,Options!$A$5:$A$104,0))),0)) -> 16500 | M5: =SUM(IFERROR(N($C5)*INDEX(Options!$U$5:$AA$104,MATCH($B5,Options!$A$5:$A$104,0),MATCH(M$4,Options!$U$4:$AA$4,0)),0),IFERROR(N($E5)*INDEX(Options!$U$5:$AA$104,MATCH($D5,Options!$A$5:$A$104,0),MATCH(M$4,Options!$U$4:$AA$4,0)),0),IFERROR(N($G5)*INDEX(Options!$U$5:$AA$104,MATCH($F5,Options!$A$5:$A$104,0),MATCH(M$4,Options!$U$4:$AA$4,0)),0),IFERROR(N($I5)*INDEX(Options!$U$5:$AA$104,MATCH($H5,Options!$A$5:$A$104,0),MATCH(M$4,Options!$U$4:$AA$4,0)),0),IFERROR(N($K5)*INDEX(Options!$U$5:$AA$104,MATCH($J5,Options!$A$5:$A$104,0),MATCH(M$4,Options!$U$4:$AA$4,0)),0)) -> 18 | N5: =SUM(IFERROR(N($C5)*INDEX(Options!$U$5:$AA$104,MATCH($B5,Options!$A$5:$A$104,0),MATCH(N$4,Options!$U$4:$AA$4,0)),0),IFERROR(N($E5)*INDEX(Options!$U$5:$AA$104,MATCH($D5,Options!$A$5:$A$104,0),MATCH(N$4,Options!$U$4:$AA$4,0)),0),IFERROR(N($G5)*INDEX(Options!$U$5:$AA$104,MATCH($F5,Options!$A$5:$A$104,0),MATCH(N$4,Options!$U$4:$AA$4,0)),0),IFERROR(N($I5)*INDEX(Options!$U$5:$AA$104,MATCH($H5,Options!$A$5:$A$104,0),MATCH(N$4,Options!$U$4:$AA$4,0)),0),IFERROR(N($K5)*INDEX(Options!$U$5:$AA$104,MATCH($J5,Options!$A$5:$A$104,0),MATCH(N$4,Options!$U$4:$AA$4,0)),0)) -> 12 | O5: =SUM(IFERROR(N($C5)*INDEX(Options!$U$5:$AA$104,MATCH($B5,Options!$A$5:$A$104,0),MATCH(O$4,Options!$U$4:$AA$4,0)),0),IFERROR(N($E5)*INDEX(Options!$U$5:$AA$104,MATCH($D5,Options!$A$5:$A$104,0),MATCH(O$4,Options!$U$4:$AA$4,0)),0),IFERROR(N($G5)*INDEX(Options!$U$5:$AA$104,MATCH($F5,Options!$A$5:$A$104,0),MATCH(O$4,Options!$U$4:$AA$4,0)),0),IFERROR(N($I5)*INDEX(Options!$U$5:$AA$104,MATCH($H5,Options!$A$5:$A$104,0),MATCH(O$4,Options!$U$4:$AA$4,0)),0),IFERROR(N($K5)*INDEX(Options!$U$5:$AA$104,MATCH($J5,Options!$A$5:$A$104,0),MATCH(O$4,Options!$U$4:$AA$4,0)),0)) -> 6 | P5: =SUM(IFERROR(N($C5)*INDEX(Options!$U$5:$AA$104,MATCH($B5,Options!$A$5:$A$104,0),MATCH(P$4,Options!$U$4:$AA$4,0)),0),IFERROR(N($E5)*INDEX(Options!$U$5:$AA$104,MATCH($D5,Options!$A$5:$A$104,0),MATCH(P$4,Options!$U$4:$AA$4,0)),0),IFERROR(N($G5)*INDEX(Options!$U$5:$AA$104,MATCH($F5,Options!$A$5:$A$104,0),MATCH(P$4,Options!$U$4:$AA$4,0)),0),IFERROR(N($I5)*INDEX(Options!$U$5:$AA$104,MATCH($H5,Options!$A$5:$A$104,0),MATCH(P$4,Options!$U$4:$AA$4,0)),0),IFERROR(N($K5)*INDEX(Options!$U$5:$AA$104,MATCH($J5,Options!$A$5:$A$104,0),MATCH(P$4,Options!$U$4:$AA$4,0)),0)) -> 0 | Q5: =SUM(IFERROR(N($C5)*INDEX(Options!$U$5:$AA$104,MATCH($B5,Options!$A$5:$A$104,0),MATCH(Q$4,Options!$U$4:$AA$4,0)),0),IFERROR(N($E5)*INDEX(Options!$U$5:$AA$104,MATCH($D5,Options!$A$5:$A$104,0),MATCH(Q$4,Options!$U$4:$AA$4,0)),0),IFERROR(N($G5)*INDEX(Options!$U$5:$AA$104,MATCH($F5,Options!$A$5:$A$104,0),MATCH(Q$4,Options!$U$4:$AA$4,0)),0),IFERROR(N($I5)*INDEX(Options!$U$5:$AA$104,MATCH($H5,Options!$A$5:$A$104,0),MATCH(Q$4,Options!$U$4:$AA$4,0)),0),IFERROR(N($K5)*INDEX(Options!$U$5:$AA$104,MATCH($J5,Options!$A$5:$A$104,0),MATCH(Q$4,Options!$U$4:$AA$4,0)),0)) -> 0 | R5: =SUM(IFERROR(N($C5)*INDEX(Options!$U$5:$AA$104,MATCH($B5,Options!$A$5:$A$104,0),MATCH(R$4,Options!$U$4:$AA$4,0)),0),IFERROR(N($E5)*INDEX(Options!$U$5:$AA$104,MATCH($D5,Options!$A$5:$A$104,0),MATCH(R$4,Options!$U$4:$AA$4,0)),0),IFERROR(N($G5)*INDEX(Options!$U$5:$AA$104,MATCH($F5,Options!$A$5:$A$104,0),MATCH(R$4,Options!$U$4:$AA$4,0)),0),IFERROR(N($I5)*INDEX(Options!$U$5:$AA$104,MATCH($H5,Options!$A$5:$A$104,0),MATCH(R$4,Options!$U$4:$AA$4,0)),0),IFERROR(N($K5)*INDEX(Options!$U$5:$AA$104,MATCH($J5,Options!$A$5:$A$104,0),MATCH(R$4,Options!$U$4:$AA$4,0)),0)) -> 0 | S5: =SUM(IFERROR(N($C5)*INDEX(Options!$U$5:$AA$104,MATCH($B5,Options!$A$5:$A$104,0),MATCH(S$4,Options!$U$4:$AA$4,0)),0),IFERROR(N($E5)*INDEX(Options!$U$5:$AA$104,MATCH($D5,Options!$A$5:$A$104,0),MATCH(S$4,Options!$U$4:$AA$4,0)),0),IFERROR(N($G5)*INDEX(Options!$U$5:$AA$104,MATCH($F5,Options!$A$5:$A$104,0),MATCH(S$4,Options!$U$4:$AA$4,0)),0),IFERROR(N($I5)*INDEX(Options!$U$5:$AA$104,MATCH($H5,Options!$A$5:$A$104,0),MATCH(S$4,Options!$U$4:$AA$4,0)),0),IFERROR(N($K5)*INDEX(Options!$U$5:$AA$104,MATCH($J5,Options!$A$5:$A$104,0),MATCH(S$4,Options!$U$4:$AA$4,0)),0)) -> 6
A6: 6 week Case 2 | B6: Balanced 45 | C6: 5 | D6: Best Free | E6: 1 | L6: =SUM(IFERROR(N($C6)*N(INDEX(Options!$P$5:$P$104,MATCH($B6,Options!$A$5:$A$104,0))),0),IFERROR(N($E6)*N(INDEX(Options!$P$5:$P$104,MATCH($D6,Options!$A$5:$A$104,0))),0),IFERROR(N($G6)*N(INDEX(Options!$P$5:$P$104,MATCH($F6,Options!$A$5:$A$104,0))),0),IFERROR(N($I6)*N(INDEX(Options!$P$5:$P$104,MATCH($H6,Options!$A$5:$A$104,0))),0),IFERROR(N($K6)*N(INDEX(Options!$P$5:$P$104,MATCH($J6,Options!$A$5:$A$104,0))),0)) -> 13750 | M6: =SUM(IFERROR(N($C6)*INDEX(Options!$U$5:$AA$104,MATCH($B6,Options!$A$5:$A$104,0),MATCH(M$4,Options!$U$4:$AA$4,0)),0),IFERROR(N($E6)*INDEX(Options!$U$5:$AA$104,MATCH($D6,Options!$A$5:$A$104,0),MATCH(M$4,Options!$U$4:$AA$4,0)),0),IFERROR(N($G6)*INDEX(Options!$U$5:$AA$104,MATCH($F6,Options!$A$5:$A$104,0),MATCH(M$4,Options!$U$4:$AA$4,0)),0),IFERROR(N($I6)*INDEX(Options!$U$5:$AA$104,MATCH($H6,Options!$A$5:$A$104,0),MATCH(M$4,Options!$U$4:$AA$4,0)),0),IFERROR(N($K6)*INDEX(Options!$U$5:$AA$104,MATCH($J6,Options!$A$5:$A$104,0),MATCH(M$4,Options!$U$4:$AA$4,0)),0)) -> 16 | N6: =SUM(IFERROR(N($C6)*INDEX(Options!$U$5:$AA$104,MATCH($B6,Options!$A$5:$A$104,0),MATCH(N$4,Options!$U$4:$AA$4,0)),0),IFERROR(N($E6)*INDEX(Options!$U$5:$AA$104,MATCH($D6,Options!$A$5:$A$104,0),MATCH(N$4,Options!$U$4:$AA$4,0)),0),IFERROR(N($G6)*INDEX(Options!$U$5:$AA$104,MATCH($F6,Options!$A$5:$A$104,0),MATCH(N$4,Options!$U$4:$AA$4,0)),0),IFERROR(N($I6)*INDEX(Options!$U$5:$AA$104,MATCH($H6,Options!$A$5:$A$104,0),MATCH(N$4,Options!$U$4:$AA$4,0)),0),IFERROR(N($K6)*INDEX(Options!$U$5:$AA$104,MATCH($J6,Options!$A$5:$A$104,0),MATCH(N$4,Options!$U$4:$AA$4,0)),0)) -> 12 | O6: =SUM(IFERROR(N($C6)*INDEX(Options!$U$5:$AA$104,MATCH($B6,Options!$A$5:$A$104,0),MATCH(O$4,Options!$U$4:$AA$4,0)),0),IFERROR(N($E6)*INDEX(Options!$U$5:$AA$104,MATCH($D6,Options!$A$5:$A$104,0),MATCH(O$4,Options!$U$4:$AA$4,0)),0),IFERROR(N($G6)*INDEX(Options!$U$5:$AA$104,MATCH($F6,Options!$A$5:$A$104,0),MATCH(O$4,Options!$U$4:$AA$4,0)),0),IFERROR(N($I6)*INDEX(Options!$U$5:$AA$104,MATCH($H6,Options!$A$5:$A$104,0),MATCH(O$4,Options!$U$4:$AA$4,0)),0),IFERROR(N($K6)*INDEX(Options!$U$5:$AA$104,MATCH($J6,Options!$A$5:$A$104,0),MATCH(O$4,Options!$U$4:$AA$4,0)),0)) -> 5 | P6: =SUM(IFERROR(N($C6)*INDEX(Options!$U$5:$AA$104,MATCH($B6,Options!$A$5:$A$104,0),MATCH(P$4,Options!$U$4:$AA$4,0)),0),IFERROR(N($E6)*INDEX(Options!$U$5:$AA$104,MATCH($D6,Options!$A$5:$A$104,0),MATCH(P$4,Options!$U$4:$AA$4,0)),0),IFERROR(N($G6)*INDEX(Options!$U$5:$AA$104,MATCH($F6,Options!$A$5:$A$104,0),MATCH(P$4,Options!$U$4:$AA$4,0)),0),IFERROR(N($I6)*INDEX(Options!$U$5:$AA$104,MATCH($H6,Options!$A$5:$A$104,0),MATCH(P$4,Options!$U$4:$AA$4,0)),0),IFERROR(N($K6)*INDEX(Options!$U$5:$AA$104,MATCH($J6,Options!$A$5:$A$104,0),MATCH(P$4,Options!$U$4:$AA$4,0)),0)) -> 0 | Q6: =SUM(IFERROR(N($C6)*INDEX(Options!$U$5:$AA$104,MATCH($B6,Options!$A$5:$A$104,0),MATCH(Q$4,Options!$U$4:$AA$4,0)),0),IFERROR(N($E6)*INDEX(Options!$U$5:$AA$104,MATCH($D6,Options!$A$5:$A$104,0),MATCH(Q$4,Options!$U$4:$AA$4,0)),0),IFERROR(N($G6)*INDEX(Options!$U$5:$AA$104,MATCH($F6,Options!$A$5:$A$104,0),MATCH(Q$4,Options!$U$4:$AA$4,0)),0),IFERROR(N($I6)*INDEX(Options!$U$5:$AA$104,MATCH($H6,Options!$A$5:$A$104,0),MATCH(Q$4,Options!$U$4:$AA$4,0)),0),IFERROR(N($K6)*INDEX(Options!$U$5:$AA$104,MATCH($J6,Options!$A$5:$A$104,0),MATCH(Q$4,Options!$U$4:$AA$4,0)),0)) -> 0 | R6: =SUM(IFERROR(N($C6)*INDEX(Options!$U$5:$AA$104,MATCH($B6,Options!$A$5:$A$104,0),MATCH(R$4,Options!$U$4:$AA$4,0)),0),IFERROR(N($E6)*INDEX(Options!$U$5:$AA$104,MATCH($D6,Options!$A$5:$A$104,0),MATCH(R$4,Options!$U$4:$AA$4,0)),0),IFERROR(N($G6)*INDEX(Options!$U$5:$AA$104,MATCH($F6,Options!$A$5:$A$104,0),MATCH(R$4,Options!$U$4:$AA$4,0)),0),IFERROR(N($I6)*INDEX(Options!$U$5:$AA$104,MATCH($H6,Options!$A$5:$A$104,0),MATCH(R$4,Options!$U$4:$AA$4,0)),0),IFERROR(N($K6)*INDEX(Options!$U$5:$AA$104,MATCH($J6,Options!$A$5:$A$104,0),MATCH(R$4,Options!$U$4:$AA$4,0)),0)) -> 0 | S6: =SUM(IFERROR(N($C6)*INDEX(Options!$U$5:$AA$104,MATCH($B6,Options!$A$5:$A$104,0),MATCH(S$4,Options!$U$4:$AA$4,0)),0),IFERROR(N($E6)*INDEX(Options!$U$5:$AA$104,MATCH($D6,Options!$A$5:$A$104,0),MATCH(S$4,Options!$U$4:$AA$4,0)),0),IFERROR(N($G6)*INDEX(Options!$U$5:$AA$104,MATCH($F6,Options!$A$5:$A$104,0),MATCH(S$4,Options!$U$4:$AA$4,0)),0),IFERROR(N($I6)*INDEX(Options!$U$5:$AA$104,MATCH($H6,Options!$A$5:$A$104,0),MATCH(S$4,Options!$U$4:$AA$4,0)),0),IFERROR(N($K6)*INDEX(Options!$U$5:$AA$104,MATCH($J6,Options!$A$5:$A$104,0),MATCH(S$4,Options!$U$4:$AA$4,0)),0)) -> 5
A7: 6 week Case 3 | B7: Balanced 65 | C7: 2 | D7: Best Free | E7: 3 | F7: Balanced 45 | G7: 1 | L7: =SUM(IFERROR(N($C7)*N(INDEX(Options!$P$5:$P$104,MATCH($B7,Options!$A$5:$A$104,0))),0),IFERROR(N($E7)*N(INDEX(Options!$P$5:$P$104,MATCH($D7,Options!$A$5:$A$104,0))),0),IFERROR(N($G7)*N(INDEX(Options!$P$5:$P$104,MATCH($F7,Options!$A$5:$A$104,0))),0),IFERROR(N($I7)*N(INDEX(Options!$P$5:$P$104,MATCH($H7,Options!$A$5:$A$104,0))),0),IFERROR(N($K7)*N(INDEX(Options!$P$5:$P$104,MATCH($J7,Options!$A$5:$A$104,0))),0)) -> 15750 | M7: =SUM(IFERROR(N($C7)*INDEX(Options!$U$5:$AA$104,MATCH($B7,Options!$A$5:$A$104,0),MATCH(M$4,Options!$U$4:$AA$4,0)),0),IFERROR(N($E7)*INDEX(Options!$U$5:$AA$104,MATCH($D7,Options!$A$5:$A$104,0),MATCH(M$4,Options!$U$4:$AA$4,0)),0),IFERROR(N($G7)*INDEX(Options!$U$5:$AA$104,MATCH($F7,Options!$A$5:$A$104,0),MATCH(M$4,Options!$U$4:$AA$4,0)),0),IFERROR(N($I7)*INDEX(Options!$U$5:$AA$104,MATCH($H7,Options!$A$5:$A$104,0),MATCH(M$4,Options!$U$4:$AA$4,0)),0),IFERROR(N($K7)*INDEX(Options!$U$5:$AA$104,MATCH($J7,Options!$A$5:$A$104,0),MATCH(M$4,Options!$U$4:$AA$4,0)),0)) -> 14 | N7: =SUM(IFERROR(N($C7)*INDEX(Options!$U$5:$AA$104,MATCH($B7,Options!$A$5:$A$104,0),MATCH(N$4,Options!$U$4:$AA$4,0)),0),IFERROR(N($E7)*INDEX(Options!$U$5:$AA$104,MATCH($D7,Options!$A$5:$A$104,0),MATCH(N$4,Options!$U$4:$AA$4,0)),0),IFERROR(N($G7)*INDEX(Options!$U$5:$AA$104,MATCH($F7,Options!$A$5:$A$104,0),MATCH(N$4,Options!$U$4:$AA$4,0)),0),IFERROR(N($I7)*INDEX(Options!$U$5:$AA$104,MATCH($H7,Options!$A$5:$A$104,0),MATCH(N$4,Options!$U$4:$AA$4,0)),0),IFERROR(N($K7)*INDEX(Options!$U$5:$AA$104,MATCH($J7,Options!$A$5:$A$104,0),MATCH(N$4,Options!$U$4:$AA$4,0)),0)) -> 18 | O7: =SUM(IFERROR(N($C7)*INDEX(Options!$U$5:$AA$104,MATCH($B7,Options!$A$5:$A$104,0),MATCH(O$4,Options!$U$4:$AA$4,0)),0),IFERROR(N($E7)*INDEX(Options!$U$5:$AA$104,MATCH($D7,Options!$A$5:$A$104,0),MATCH(O$4,Options!$U$4:$AA$4,0)),0),IFERROR(N($G7)*INDEX(Options!$U$5:$AA$104,MATCH($F7,Options!$A$5:$A$104,0),MATCH(O$4,Options!$U$4:$AA$4,0)),0),IFERROR(N($I7)*INDEX(Options!$U$5:$AA$104,MATCH($H7,Options!$A$5:$A$104,0),MATCH(O$4,Options!$U$4:$AA$4,0)),0),IFERROR(N($K7)*INDEX(Options!$U$5:$AA$104,MATCH($J7,Options!$A$5:$A$104,0),MATCH(O$4,Options!$U$4:$AA$4,0)),0)) -> 5 | P7: =SUM(IFERROR(N($C7)*INDEX(Options!$U$5:$AA$104,MATCH($B7,Options!$A$5:$A$104,0),MATCH(P$4,Options!$U$4:$AA$4,0)),0),IFERROR(N($E7)*INDEX(Options!$U$5:$AA$104,MATCH($D7,Options!$A$5:$A$104,0),MATCH(P$4,Options!$U$4:$AA$4,0)),0),IFERROR(N($G7)*INDEX(Options!$U$5:$AA$104,MATCH($F7,Options!$A$5:$A$104,0),MATCH(P$4,Options!$U$4:$AA$4,0)),0),IFERROR(N($I7)*INDEX(Options!$U$5:$AA$104,MATCH($H7,Options!$A$5:$A$104,0),MATCH(P$4,Options!$U$4:$AA$4,0)),0),IFERROR(N($K7)*INDEX(Options!$U$5:$AA$104,MATCH($J7,Options!$A$5:$A$104,0),MATCH(P$4,Options!$U$4:$AA$4,0)),0)) -> 0 | Q7: =SUM(IFERROR(N($C7)*INDEX(Options!$U$5:$AA$104,MATCH($B7,Options!$A$5:$A$104,0),MATCH(Q$4,Options!$U$4:$AA$4,0)),0),IFERROR(N($E7)*INDEX(Options!$U$5:$AA$104,MATCH($D7,Options!$A$5:$A$104,0),MATCH(Q$4,Options!$U$4:$AA$4,0)),0),IFERROR(N($G7)*INDEX(Options!$U$5:$AA$104,MATCH($F7,Options!$A$5:$A$104,0),MATCH(Q$4,Options!$U$4:$AA$4,0)),0),IFERROR(N($I7)*INDEX(Options!$U$5:$AA$104,MATCH($H7,Options!$A$5:$A$104,0),MATCH(Q$4,Options!$U$4:$AA$4,0)),0),IFERROR(N($K7)*INDEX(Options!$U$5:$AA$104,MATCH($J7,Options!$A$5:$A$104,0),MATCH(Q$4,Options!$U$4:$AA$4,0)),0)) -> 0 | R7: =SUM(IFERROR(N($C7)*INDEX(Options!$U$5:$AA$104,MATCH($B7,Options!$A$5:$A$104,0),MATCH(R$4,Options!$U$4:$AA$4,0)),0),IFERROR(N($E7)*INDEX(Options!$U$5:$AA$104,MATCH($D7,Options!$A$5:$A$104,0),MATCH(R$4,Options!$U$4:$AA$4,0)),0),IFERROR(N($G7)*INDEX(Options!$U$5:$AA$104,MATCH($F7,Options!$A$5:$A$104,0),MATCH(R$4,Options!$U$4:$AA$4,0)),0),IFERROR(N($I7)*INDEX(Options!$U$5:$AA$104,MATCH($H7,Options!$A$5:$A$104,0),MATCH(R$4,Options!$U$4:$AA$4,0)),0),IFERROR(N($K7)*INDEX(Options!$U$5:$AA$104,MATCH($J7,Options!$A$5:$A$104,0),MATCH(R$4,Options!$U$4:$AA$4,0)),0)) -> 0 | S7: =SUM(IFERROR(N($C7)*INDEX(Options!$U$5:$AA$104,MATCH($B7,Options!$A$5:$A$104,0),MATCH(S$4,Options!$U$4:$AA$4,0)),0),IFERROR(N($E7)*INDEX(Options!$U$5:$AA$104,MATCH($D7,Options!$A$5:$A$104,0),MATCH(S$4,Options!$U$4:$AA$4,0)),0),IFERROR(N($G7)*INDEX(Options!$U$5:$AA$104,MATCH($F7,Options!$A$5:$A$104,0),MATCH(S$4,Options!$U$4:$AA$4,0)),0),IFERROR(N($I7)*INDEX(Options!$U$5:$AA$104,MATCH($H7,Options!$A$5:$A$104,0),MATCH(S$4,Options!$U$4:$AA$4,0)),0),IFERROR(N($K7)*INDEX(Options!$U$5:$AA$104,MATCH($J7,Options!$A$5:$A$104,0),MATCH(S$4,Options!$U$4:$AA$4,0)),0)) -> 5
